Workbook

Sheet Estimates & Accuracy - Web
A1: Project | B1: User Story Key | C1: Actual Effort (PH) | D1: Expert Judgement Single Point | G1: Planning Poker | M1: ChatGPT | P1: DeepSeek | S1: Copilot | V1: Gemini
D2: Estimates (PH) | E2: MRE | F2: ± 25% | G2: Estimates (PH) | H2: Effort (Hours) | I2: Effort (PH) | J2: Iterations | K2: MRE | L2: ± 25% | M2: Estimates (PH) | N2: MRE | O2: ± 25% | P2: Estimates (PH) | Q2: MRE | R2: ± 25% | S2: Estimates (PH) | T2: MRE | U2: ± 25% | V2: Estimates (PH) | W2: MRE | X2: ± 25%
A3: C1P1 | B3: C1P1U1 | C3: 24.5 | D3: 32 | E3: =ABS(C3-D3)/C3 -> 0.30612245 | F3: =IF(E3<=0.25,TRUE,FALSE) -> FALSE | G3: 40 | H3: 0.185556 | I3: =H3*5 -> 0.92778 | J3: 3 | K3: =ABS(C3-G3)/C3 -> 0.63265306 | L3: =IF(K3<=0.25,TRUE,FALSE) -> FALSE | M3: 52 | N3: =ABS(C3-M3)/C3 -> 1.122449 | O3: =IF(N3<=0.25,TRUE,FALSE) -> FALSE | P3: 95 | Q3: =ABS(C3-P3)/C3 -> 2.877551 | R3: =IF(Q3<=0.25,TRUE,FALSE) -> FALSE | S3: 118 | T3: =ABS(C3-S3)/C3 -> 3.8163265 | U3: =IF(T3<=0.25,TRUE,FALSE) -> FALSE | V3: 74 | W3: =ABS(C3-V3)/C3 -> 2.0204082 | X3: =IF(W3<=0.25,TRUE,FALSE) -> FALSE
B4: C1P1U2 | C4: 37 | D4: 30 | E4: =ABS(C4-D4)/C4 -> 0.18918919 | F4: =IF(E4<=0.25,TRUE,FALSE) -> TRUE | G4: 64 | H4: 0.173611 | I4: =H4*5 -> 0.868055 | J4: 3 | K4: =ABS(C4-G4)/C4 -> 0.72972973 | L4: =IF(K4<=0.25,TRUE,FALSE) -> FALSE | M4: 86 | N4: =ABS(C4-M4)/C4 -> 1.3243243 | O4: =IF(N4<=0.25,TRUE,FALSE) -> FALSE | P4: 106 | Q4: =ABS(C4-P4)/C4 -> 1.8648649 | R4: =IF(Q4<=0.25,TRUE,FALSE) -> FALSE | S4: 174 | T4: =ABS(C4-S4)/C4 -> 3.7027027 | U4: =IF(T4<=0.25,TRUE,FALSE) -> FALSE | V4: 105 | W4: =ABS(C4-V4)/C4 -> 1.8378378 | X4: =IF(W4<=0.25,TRUE,FALSE) -> FALSE
B5: C1P1U3 | C5: 32 | D5: 32 | E5: =ABS(C5-D5)/C5 -> 0 | F5: =IF(E5<=0.25,TRUE,FALSE) -> TRUE | G5: 40 | H5: 0.3525 | I5: =H5*5 -> 1.7625 | J5: 2 | K5: =ABS(C5-G5)/C5 -> 0.25 | L5: =IF(K5<=0.25,TRUE,FALSE) -> TRUE | M5: 57 | N5: =ABS(C5-M5)/C5 -> 0.78125 | O5: =IF(N5<=0.25,TRUE,FALSE) -> FALSE | P5: 56 | Q5: =ABS(C5-P5)/C5 -> 0.75 | R5: =IF(Q5<=0.25,TRUE,FALSE) -> FALSE | S5: 168 | T5: =ABS(C5-S5)/C5 -> 4.25 | U5: =IF(T5<=0.25,TRUE,FALSE) -> FALSE | V5: 100 | W5: =ABS(C5-V5)/C5 -> 2.125 | X5: =IF(W5<=0.25,TRUE,FALSE) -> FALSE
B6: C1P1U4 | C6: 25 | D6: 24 | E6: =ABS(C6-D6)/C6 -> 0.04 | F6: =IF(E6<=0.25,TRUE,FALSE) -> TRUE | G6: 24 | H6: 0.121389 | I6: =H6*5 -> 0.606945 | J6: 3 | K6: =ABS(C6-G6)/C6 -> 0.04 | L6: =IF(K6<=0.25,TRUE,FALSE) -> TRUE | M6: 92 | N6: =ABS(C6-M6)/C6 -> 2.68 | O6: =IF(N6<=0.25,TRUE,FALSE) -> FALSE | P6: 296 | Q6: =ABS(C6-P6)/C6 -> 10.84 | R6: =IF(Q6<=0.25,TRUE,FALSE) -> FALSE | S6: 146 | T6: =ABS(C6-S6)/C6 -> 4.84 | U6: =IF(T6<=0.25,TRUE,FALSE) -> FALSE | V6: 270 | W6: =ABS(C6-V6)/C6 -> 9.8 | X6: =IF(W6<=0.25,TRUE,FALSE) -> FALSE
B7: C1P1U5 | C7: 25 | D7: 36 | E7: =ABS(C7-D7)/C7 -> 0.44 | F7: =IF(E7<=0.25,TRUE,FALSE) -> FALSE | G7: 40 | H7: 0.31722222 | I7: =H7*5 -> 1.5861111 | J7: 2 | K7: =ABS(C7-G7)/C7 -> 0.6 | L7: =IF(K7<=0.25,TRUE,FALSE) -> FALSE | M7: 128 | N7: =ABS(C7-M7)/C7 -> 4.12 | O7: =IF(N7<=0.25,TRUE,FALSE) -> FALSE | P7: 212 | Q7: =ABS(C7-P7)/C7 -> 7.48 | R7: =IF(Q7<=0.25,TRUE,FALSE) -> FALSE | S7: 140 | T7: =ABS(C7-S7)/C7 -> 4.6 | U7: =IF(T7<=0.25,TRUE,FALSE) -> FALSE | V7: 406 | W7: =ABS(C7-V7)/C7 -> 15.24 | X7: =IF(W7<=0.25,TRUE,FALSE) -> FALSE
B8: C1P1U6 | C8: 14 | D8: 16 | E8: =ABS(C8-D8)/C8 -> 0.14285714 | F8: =IF(E8<=0.25,TRUE,FALSE) -> TRUE | G8: 16 | H8: 0.101111 | I8: =H8*5 -> 0.505555 | J8: 2 | K8: =ABS(C8-G8)/C8 -> 0.14285714 | L8: =IF(K8<=0.25,TRUE,FALSE) -> TRUE | M8: 91 | N8: =ABS(C8-M8)/C8 -> 5.5 | O8: =IF(N8<=0.25,TRUE,FALSE) -> FALSE | P8: 224 | Q8: =ABS(C8-P8)/C8 -> 15 | R8: =IF(Q8<=0.25,TRUE,FALSE) -> FALSE | S8: 94 | T8: =ABS(C8-S8)/C8 -> 5.7142857 | U8: =IF(T8<=0.25,TRUE,FALSE) -> FALSE | V8: 440 | W8: =ABS(C8-V8)/C8 -> 30.428571 | X8: =IF(W8<=0.25,TRUE,FALSE) -> FALSE
B9: C1P1U7 | C9: 9.25 | D9: 7 | E9: =ABS(C9-D9)/C9 -> 0.24324324 | F9: =IF(E9<=0.25,TRUE,FALSE) -> TRUE | G9: 8 | H9: 0.158611 | I9: =H9*5 -> 0.793055 | J9: 2 | K9: =ABS(C9-G9)/C9 -> 0.13513514 | L9: =IF(K9<=0.25,TRUE,FALSE) -> TRUE | M9: 70 | N9: =ABS(C9-M9)/C9 -> 6.5675676 | O9: =IF(N9<=0.25,TRUE,FALSE) -> FALSE | P9: 64 | Q9: =ABS(C9-P9)/C9 -> 5.9189189 | R9: =IF(Q9<=0.25,TRUE,FALSE) -> FALSE | S9: 53 | T9: =ABS(C9-S9)/C9 -> 4.7297297 | U9: =IF(T9<=0.25,TRUE,FALSE) -> FALSE | V9: 308 | W9: =ABS(C9-V9)/C9 -> 32.297297 | X9: =IF(W9<=0.25,TRUE,FALSE) -> FALSE
A10: Total | C10: =SUM(C3:C9) -> 166.75 | D10: =SUM(D3:D9) -> 177 | E10: =AVERAGE(E3:E9) -> 0.19448743 | F10: =COUNTIF(F3:F9, TRUE)/ROWS(B3:B9) -> 0.71428571 | G10: =SUM(G3:G9) -> 232 | H10: =SUM(H3:H9) -> 1.4100002 | I10: =SUM(I3:I9) -> 7.0500011 | J10: =SUM(J3:J9) -> 17 | K10: =AVERAGE(K3:K9) -> 0.36148215 | L10: =COUNTIF(L3:L9, TRUE)/ROWS(B3:B9) -> 0.57142857 | M10: =SUM(M3:M9) -> 576 | N10: =AVERAGE(N3:N9) -> 3.156513 | O10: =COUNTIF(O3:O9, TRUE)/ROWS(B3:B9) -> 0 | P10: =SUM(P3:P9) -> 1053 | Q10: =AVERAGE(Q3:Q9) -> 6.3901907 | R10: =COUNTIF(R3:R9, TRUE)/ROWS(B3:B9) -> 0 | S10: =SUM(S3:S9) -> 893 | T10: =AVERAGE(T3:T9) -> 4.5218635 | U10: =COUNTIF(U3:U9, TRUE)/ROWS(B3:B9) -> 0 | V10: =SUM(V3:V9) -> 1703 | W10: =AVERAGE(W3:W9) -> 13.392731 | X10: =COUNTIF(X3:X9, TRUE)/ROWS(B3:B9) -> 0
A11: C1P2 | B11: C1P2U1 | C11: 44.5 | D11: 50 | E11: =ABS(C11-D11)/C11 -> 0.12359551 | F11: =IF(E11<=0.25,TRUE,FALSE) -> TRUE | G11: 64 | H11: 0.177778 | I11: =H11*5 -> 0.88889 | J11: 3 | K11: =ABS(C11-G11)/C11 -> 0.43820225 | L11: =IF(K11<=0.25,TRUE,FALSE) -> FALSE | M11: 42 | N11: =ABS(C11-M11)/C11 -> 0.056179775 | O11: =IF(N11<=0.25,TRUE,FALSE) -> TRUE | P11: 42 | Q11: =ABS(C11-P11)/C11 -> 0.056179775 | R11: =IF(Q11<=0.25,TRUE,FALSE) -> TRUE | S11: 55 | T11: =ABS(C11-S11)/C11 -> 0.23595506 | U11: =IF(T11<=0.25,TRUE,FALSE) -> TRUE | V11: 190 | W11: =ABS(C11-V11)/C11 -> 3.2696629 | X11: =IF(W11<=0.25,TRUE,FALSE) -> FALSE
B12: C1P2U2 | C12: 38.5 | D12: 32 | E12: =ABS(C12-D12)/C12 -> 0.16883117 | F12: =IF(E12<=0.25,TRUE,FALSE) -> TRUE | G12: 40 | H12: 0.0969444 | I12: =H12*5 -> 0.484722 | J12: 2 | K12: =ABS(C12-G12)/C12 -> 0.038961039 | L12: =IF(K12<=0.25,TRUE,FALSE) -> TRUE | M12: 46 | N12: =ABS(C12-M12)/C12 -> 0.19480519 | O12: =IF(N12<=0.25,TRUE,FALSE) -> TRUE | P12: 45 | Q12: =ABS(C12-P12)/C12 -> 0.16883117 | R12: =IF(Q12<=0.25,TRUE,FALSE) -> TRUE | S12: 53 | T12: =ABS(C12-S12)/C12 -> 0.37662338 | U12: =IF(T12<=0.25,TRUE,FALSE) -> FALSE | V12: 80 | W12: =ABS(C12-V12)/C12 -> 1.0779221 | X12: =IF(W12<=0.25,TRUE,FALSE) -> FALSE
B13: C1P2U3 | C13: 33 | D13: 31.5 | E13: =ABS(C13-D13)/C13 -> 0.045454545 | F13: =IF(E13<=0.25,TRUE,FALSE) -> TRUE | G13: 40 | H13: 0.197222 | I13: =H13*5 -> 0.98611 | J13: 3 | K13: =ABS(C13-G13)/C13 -> 0.21212121 | L13: =IF(K13<=0.25,TRUE,FALSE) -> TRUE | M13: 80 | N13: =ABS(C13-M13)/C13 -> 1.4242424 | O13: =IF(N13<=0.25,TRUE,FALSE) -> FALSE | P13: 46 | Q13: =ABS(C13-P13)/C13 -> 0.39393939 | R13: =IF(Q13<=0.25,TRUE,FALSE) -> FALSE | S13: 94 | T13: =ABS(C13-S13)/C13 -> 1.8484848 | U13: =IF(T13<=0.25,TRUE,FALSE) -> FALSE | V13: 158 | W13: =ABS(C13-V13)/C13 -> 3.7878788 | X13: =IF(W13<=0.25,TRUE,FALSE) -> FALSE
B14: C1P2U4 | C14: 54 | D14: 57 | E14: =ABS(C14-D14)/C14 -> 0.055555556 | F14: =IF(E14<=0.25,TRUE,FALSE) -> TRUE | G14: 64 | H14: 0.0966667 | I14: =H14*5 -> 0.4833335 | J14: 2 | K14: =ABS(C14-G14)/C14 -> 0.18518519 | L14: =IF(K14<=0.25,TRUE,FALSE) -> TRUE | M14: 50 | N14: =ABS(C14-M14)/C14 -> 0.074074074 | O14: =IF(N14<=0.25,TRUE,FALSE) -> TRUE | P14: 62 | Q14: =ABS(C14-P14)/C14 -> 0.14814815 | R14: =IF(Q14<=0.25,TRUE,FALSE) -> TRUE | S14: 88 | T14: =ABS(C14-S14)/C14 -> 0.62962963 | U14: =IF(T14<=0.25,TRUE,FALSE) -> FALSE | V14: 72 | W14: =ABS(C14-V14)/C14 -> 0.33333333 | X14: =IF(W14<=0.25,TRUE,FALSE) -> FALSE
B15: C1P2U5 | C15: 57.5 | D15: 48 | E15: =ABS(C15-D15)/C15 -> 0.16521739 | F15: =IF(E15<=0.25,TRUE,FALSE) -> TRUE | G15: 64 | H15: 0.244722 | I15: =H15*5 -> 1.22361 | J15: 2 | K15: =ABS(C15-G15)/C15 -> 0.11304348 | L15: =IF(K15<=0.25,TRUE,FALSE) -> TRUE | M15: 76 | N15: =ABS(C15-M15)/C15 -> 0.32173913 | O15: =IF(N15<=0.25,TRUE,FALSE) -> FALSE | P15: 70 | Q15: =ABS(C15-P15)/C15 -> 0.2173913 | R15: =IF(Q15<=0.25,TRUE,FALSE) -> TRUE | S15: 91 | T15: =ABS(C15-S15)/C15 -> 0.5826087 | U15: =IF(T15<=0.25,TRUE,FALSE) -> FALSE | V15: 168 | W15: =ABS(C15-V15)/C15 -> 1.9217391 | X15: =IF(W15<=0.25,TRUE,FALSE) -> FALSE
B16: C1P2U6 | C16: 27 | D16: 35 | E16: =ABS(C16-D16)/C16 -> 0.2962963 | F16: =IF(E16<=0.25,TRUE,FALSE) -> FALSE | G16: 40 | H16: 0.102778 | I16: =H16*5 -> 0.51389 | J16: 3 | K16: =ABS(C16-G16)/C16 -> 0.48148148 | L16: =IF(K16<=0.25,TRUE,FALSE) -> FALSE | M16: 41 | N16: =ABS(C16-M16)/C16 -> 0.51851852 | O16: =IF(N16<=0.25,TRUE,FALSE) -> FALSE | P16: 32 | Q16: =ABS(C16-P16)/C16 -> 0.18518519 | R16: =IF(Q16<=0.25,TRUE,FALSE) -> TRUE | S16: 36 | T16: =ABS(C16-S16)/C16 -> 0.33333333 | U16: =IF(T16<=0.25,TRUE,FALSE) -> FALSE | V16: 104 | W16: =ABS(C16-V16)/C16 -> 2.8518519 | X16: =IF(W16<=0.25,TRUE,FALSE) -> FALSE
B17: C1P2U7 | C17: 37.5 | D17: 44 | E17: =ABS(C17-D17)/C17 -> 0.17333333 | F17: =IF(E17<=0.25,TRUE,FALSE) -> TRUE | G17: 40 | H17: 0.219722 | I17: =H17*5 -> 1.09861 | J17: 1 | K17: =ABS(C17-G17)/C17 -> 0.066666667 | L17: =IF(K17<=0.25,TRUE,FALSE) -> TRUE | M17: 44 | N17: =ABS(C17-M17)/C17 -> 0.17333333 | O17: =IF(N17<=0.25,TRUE,FALSE) -> TRUE | P17: 80 | Q17: =ABS(C17-P17)/C17 -> 1.1333333 | R17: =IF(Q17<=0.25,TRUE,FALSE) -> FALSE | S17: 83 | T17: =ABS(C17-S17)/C17 -> 1.2133333 | U17: =IF(T17<=0.25,TRUE,FALSE) -> FALSE | V17: 80 | W17: =ABS(C17-V17)/C17 -> 1.1333333 | X17: =IF(W17<=0.25,TRUE,FALSE) -> FALSE
B18: C1P2U8 | C18: 10.75 | D18: 8 | E18: =ABS(C18-D18)/C18 -> 0.25581395 | F18: =IF(E18<=0.25,TRUE,FALSE) -> FALSE | G18: 16 | H18: 0.0991667 | I18: =H18*5 -> 0.4958335 | J18: 2 | K18: =ABS(C18-G18)/C18 -> 0.48837209 | L18: =IF(K18<=0.25,TRUE,FALSE) -> FALSE | M18: 22 | N18: =ABS(C18-M18)/C18 -> 1.0465116 | O18: =IF(N18<=0.25,TRUE,FALSE) -> FALSE | P18: 32 | Q18: =ABS(C18-P18)/C18 -> 1.9767442 | R18: =IF(Q18<=0.25,TRUE,FALSE) -> FALSE | S18: 35 | T18: =ABS(C18-S18)/C18 -> 2.255814 | U18: =IF(T18<=0.25,TRUE,FALSE) -> FALSE | V18: 48 | W18: =ABS(C18-V18)/C18 -> 3.4651163 | X18: =IF(W18<=0.25,TRUE,FALSE) -> FALSE
B19: C1P2U9 | C19: 47.75 | D19: 40 | E19: =ABS(C19-D19)/C19 -> 0.16230366 | F19: =IF(E19<=0.25,TRUE,FALSE) -> TRUE | G19: 40 | H19: 0.152222 | I19: =H19*5 -> 0.76111 | J19: 2 | K19: =ABS(C19-G19)/C19 -> 0.16230366 | L19: =IF(K19<=0.25,TRUE,FALSE) -> TRUE | M19: 53 | N19: =ABS(C19-M19)/C19 -> 0.10994764 | O19: =IF(N19<=0.25,TRUE,FALSE) -> TRUE | P19: 72 | Q19: =ABS(C19-P19)/C19 -> 0.5078534 | R19: =IF(Q19<=0.25,TRUE,FALSE) -> FALSE | S19: 122 | T19: =ABS(C19-S19)/C19 -> 1.5549738 | U19: =IF(T19<=0.25,TRUE,FALSE) -> FALSE | V19: 72 | W19: =ABS(C19-V19)/C19 -> 0.5078534 | X19: =IF(W19<=0.25,TRUE,FALSE) -> FALSE
B20: C1P2U10 | C20: 35.5 | D20: 40 | E20: =ABS(C20-D20)/C20 -> 0.12676056 | F20: =IF(E20<=0.25,TRUE,FALSE) -> TRUE | G20: 40 | H20: 0.0925 | I20: =H20*5 -> 0.4625 | J20: 2 | K20: =ABS(C20-G20)/C20 -> 0.12676056 | L20: =IF(K20<=0.25,TRUE,FALSE) -> TRUE | M20: 52 | N20: =ABS(C20-M20)/C20 -> 0.46478873 | O20: =IF(N20<=0.25,TRUE,FALSE) -> FALSE | P20: 88 | Q20: =ABS(C20-P20)/C20 -> 1.4788732 | R20: =IF(Q20<=0.25,TRUE,FALSE) -> FALSE | S20: 108 | T20: =ABS(C20-S20)/C20 -> 2.0422535 | U20: =IF(T20<=0.25,TRUE,FALSE) -> FALSE | V20: 108 | W20: =ABS(C20-V20)/C20 -> 2.0422535 | X20: =IF(W20<=0.25,TRUE,FALSE) -> FALSE
B21: C1P2U11 | C21: 47 | D21: 43.5 | E21: =ABS(C21-D21)/C21 -> 0.074468085 | F21: =IF(E21<=0.25,TRUE,FALSE) -> TRUE | G21: 64 | H21: 0.162222 | I21: =H21*5 -> 0.81111 | J21: 3 | K21: =ABS(C21-G21)/C21 -> 0.36170213 | L21: =IF(K21<=0.25,TRUE,FALSE) -> FALSE | M21: 66 | N21: =ABS(C21-M21)/C21 -> 0.40425532 | O21: =IF(N21<=0.25,TRUE,FALSE) -> FALSE | P21: 76 | Q21: =ABS(C21-P21)/C21 -> 0.61702128 | R21: =IF(Q21<=0.25,TRUE,FALSE) -> FALSE | S21: 93 | T21: =ABS(C21-S21)/C21 -> 0.9787234 | U21: =IF(T21<=0.25,TRUE,FALSE) -> FALSE | V21: 100 | W21: =ABS(C21-V21)/C21 -> 1.1276596 | X21: =IF(W21<=0.25,TRUE,FALSE) -> FALSE
B22: C1P2U12 | C22: 28 | D22: 20 | E22: =ABS(C22-D22)/C22 -> 0.28571429 | F22: =IF(E22<=0.25,TRUE,FALSE) -> FALSE | G22: 40 | H22: 0.1225 | I22: =H22*5 -> 0.6125 | J22: 3 | K22: =ABS(C22-G22)/C22 -> 0.42857143 | L22: =IF(K22<=0.25,TRUE,FALSE) -> FALSE | M22: 24 | N22: =ABS(C22-M22)/C22 -> 0.14285714 | O22: =IF(N22<=0.25,TRUE,FALSE) -> TRUE | P22: 50 | Q22: =ABS(C22-P22)/C22 -> 0.78571429 | R22: =IF(Q22<=0.25,TRUE,FALSE) -> FALSE | S22: 65 | T22: =ABS(C22-S22)/C22 -> 1.3214286 | U22: =IF(T22<=0.25,TRUE,FALSE) -> FALSE | V22: 111 | W22: =ABS(C22-V22)/C22 -> 2.9642857 | X22: =IF(W22<=0.25,TRUE,FALSE) -> FALSE
B23: C1P2U13 | C23: 28 | D23: 20 | E23: =ABS(C23-D23)/C23 -> 0.28571429 | F23: =IF(E23<=0.25,TRUE,FALSE) -> FALSE | G23: 64 | H23: 0.14055556 | I23: =H23*5 -> 0.70277778 | J23: 2 | K23: =ABS(C23-G23)/C23 -> 1.2857143 | L23: =IF(K23<=0.25,TRUE,FALSE) -> FALSE | M23: 46 | N23: =ABS(C23-M23)/C23 -> 0.64285714 | O23: =IF(N23<=0.25,TRUE,FALSE) -> FALSE | P23: 68 | Q23: =ABS(C23-P23)/C23 -> 1.4285714 | R23: =IF(Q23<=0.25,TRUE,FALSE) -> FALSE | S23: 49 | T23: =ABS(C23-S23)/C23 -> 0.75 | U23: =IF(T23<=0.25,TRUE,FALSE) -> FALSE | V23: 44 | W23: =ABS(C23-V23)/C23 -> 0.57142857 | X23: =IF(W23<=0.25,TRUE,FALSE) -> FALSE
A24: Total | C24: =SUM(C11:C23) -> 489 | D24: =SUM(D11:D23) -> 469 | E24: =AVERAGE(E11:E23) -> 0.17069682 | F24: =COUNTIF(F11:F23, TRUE)/ROWS(B11:B23) -> 0.69230769 | G24: =SUM(G11:G23) -> 616 | H24: =SUM(H11:H23) -> 1.9049994 | I24: =SUM(I11:I23) -> 9.5249968 | J24: =SUM(J11:J23) -> 30 | K24: =AVERAGE(K11:K23) -> 0.33762196 | L24: =COUNTIF(L11:L23, TRUE)/ROWS(B11:B23) -> 0.53846154 | M24: =SUM(M11:M23) -> 642 | N24: =AVERAGE(N11:N23) -> 0.4287777 | O24: =COUNTIF(O11:O23, TRUE)/ROWS(B11:B23) -> 0.46153846 | P24: =SUM(P11:P23) -> 763 | Q24: =AVERAGE(Q11:Q23) -> 0.6998297 | R24: =COUNTIF(R11:R23, TRUE)/ROWS(B11:B23) -> 0.38461538 | S24: =SUM(S11:S23) -> 972 | T24: =AVERAGE(T11:T23) -> 1.086397 | U24: =COUNTIF(U11:U23, TRUE)/ROWS(B11:B23) -> 0.076923077 | V24: =SUM(V11:V23) -> 1335 | W24: =AVERAGE(W11:W23) -> 1.9272553 | X24: =COUNTIF(X11:X23, TRUE)/ROWS(B11:B23) -> 0
A25: C2P1 | B25: C2P1U1 | C25: 28 | D25: 20 | E25: =ABS(C25-D25)/C25 -> 0.28571429 | F25: =IF(E25<=0.25,TRUE,FALSE) -> FALSE | G25: 64 | H25: 0.12166667 | I25: =H25*5 -> 0.60833333 | J25: 3 | K25: =ABS(C25-G25)/C25 -> 1.2857143 | L25: =IF(K25<=0.25,TRUE,FALSE) -> FALSE | M25: 60 | N25: =ABS(C25-M25)/C25 -> 1.1428571 | O25: =IF(N25<=0.25,TRUE,FALSE) -> FALSE | P25: 90 | Q25: =ABS(C25-P25)/C25 -> 2.2142857 | R25: =IF(Q25<=0.25,TRUE,FALSE) -> FALSE | S25: 82 | T25: =ABS(C25-S25)/C25 -> 1.9285714 | U25: =IF(T25<=0.25,TRUE,FALSE) -> FALSE | V25: 224 | W25: =ABS(C25-V25)/C25 -> 7 | X25: =IF(W25<=0.25,TRUE,FALSE) -> FALSE
B26: C2P1U2 | C26: 82.5 | D26: 64 | E26: =ABS(C26-D26)/C26 -> 0.22424242 | F26: =IF(E26<=0.25,TRUE,FALSE) -> TRUE | G26: 104 | H26: 0.17138889 | I26: =H26*5 -> 0.85694444 | J26: 2 | K26: =ABS(C26-G26)/C26 -> 0.26060606 | L26: =IF(K26<=0.25,TRUE,FALSE) -> FALSE | M26: 105 | N26: =ABS(C26-M26)/C26 -> 0.27272727 | O26: =IF(N26<=0.25,TRUE,FALSE) -> FALSE | P26: 160 | Q26: =ABS(C26-P26)/C26 -> 0.93939394 | R26: =IF(Q26<=0.25,TRUE,FALSE) -> FALSE | S26: 150 | T26: =ABS(C26-S26)/C26 -> 0.81818182 | U26: =IF(T26<=0.25,TRUE,FALSE) -> FALSE | V26: 152 | W26: =ABS(C26-V26)/C26 -> 0.84242424 | X26: =IF(W26<=0.25,TRUE,FALSE) -> FALSE
B27: C2P1U3 | C27: 59.6 | D27: 56 | E27: =ABS(C27-D27)/C27 -> 0.060402685 | F27: =IF(E27<=0.25,TRUE,FALSE) -> TRUE | G27: 64 | H27: 0.11694444 | I27: =H27*5 -> 0.58472222 | J27: 3 | K27: =ABS(C27-G27)/C27 -> 0.073825503 | L27: =IF(K27<=0.25,TRUE,FALSE) -> TRUE | M27: 57 | N27: =ABS(C27-M27)/C27 -> 0.043624161 | O27: =IF(N27<=0.25,TRUE,FALSE) -> TRUE | P27: 84 | Q27: =ABS(C27-P27)/C27 -> 0.40939597 | R27: =IF(Q27<=0.25,TRUE,FALSE) -> FALSE | S27: 78 | T27: =ABS(C27-S27)/C27 -> 0.30872483 | U27: =IF(T27<=0.25,TRUE,FALSE) -> FALSE | V27: 88 | W27: =ABS(C27-V27)/C27 -> 0.47651007 | X27: =IF(W27<=0.25,TRUE,FALSE) -> FALSE
B28: C2P1U4 | C28: 26 | D28: 12 | E28: =ABS(C28-D28)/C28 -> 0.53846154 | F28: =IF(E28<=0.25,TRUE,FALSE) -> FALSE | G28: 24 | H28: 0.12583333 | I28: =H28*5 -> 0.62916667 | J28: 2 | K28: =ABS(C28-G28)/C28 -> 0.076923077 | L28: =IF(K28<=0.25,TRUE,FALSE) -> TRUE | M28: 50 | N28: =ABS(C28-M28)/C28 -> 0.92307692 | O28: =IF(N28<=0.25,TRUE,FALSE) -> FALSE | P28: 96 | Q28: =ABS(C28-P28)/C28 -> 2.6923077 | R28: =IF(Q28<=0.25,TRUE,FALSE) -> FALSE | S28: 66 | T28: =ABS(C28-S28)/C28 -> 1.5384615 | U28: =IF(T28<=0.25,TRUE,FALSE) -> FALSE | V28: 88 | W28: =ABS(C28-V28)/C28 -> 2.3846154 | X28: =IF(W28<=0.25,TRUE,FALSE) -> FALSE
B29: C2P1U5 | C29: 44 | D29: 32 | E29: =ABS(C29-D29)/C29 -> 0.27272727 | F29: =IF(E29<=0.25,TRUE,FALSE) -> FALSE | G29: 40 | H29: 0.10583333 | I29: =H29*5 -> 0.52916667 | J29: 2 | K29: =ABS(C29-G29)/C29 -> 0.090909091 | L29: =IF(K29<=0.25,TRUE,FALSE) -> TRUE | M29: 76 | N29: =ABS(C29-M29)/C29 -> 0.72727273 | O29: =IF(N29<=0.25,TRUE,FALSE) -> FALSE | P29: 152 | Q29: =ABS(C29-P29)/C29 -> 2.4545455 | R29: =IF(Q29<=0.25,TRUE,FALSE) -> FALSE | S29: 142 | T29: =ABS(C29-S29)/C29 -> 2.2272727 | U29: =IF(T29<=0.25,TRUE,FALSE) -> FALSE | V29: 180 | W29: =ABS(C29-V29)/C29 -> 3.0909091 | X29: =IF(W29<=0.25,TRUE,FALSE) -> FALSE
B30: C2P1U6 | C30: 137.25 | D30: 88 | E30: =ABS(C30-D30)/C30 -> 0.35883424 | F30: =IF(E30<=0.25,TRUE,FALSE) -> FALSE | G30: 104 | H30: 0.13861111 | I30: =H30*5 -> 0.69305556 | J30: 2 | K30: =ABS(C30-G30)/C30 -> 0.24225865 | L30: =IF(K30<=0.25,TRUE,FALSE) -> TRUE | M30: 120 | N30: =ABS(C30-M30)/C30 -> 0.12568306 | O30: =IF(N30<=0.25,TRUE,FALSE) -> TRUE | P30: 110 | Q30: =ABS(C30-P30)/C30 -> 0.19854281 | R30: =IF(Q30<=0.25,TRUE,FALSE) -> TRUE | S30: 65 | T30: =ABS(C30-S30)/C30 -> 0.52641166 | U30: =IF(T30<=0.25,TRUE,FALSE) -> FALSE | V30: 424 | W30: =ABS(C30-V30)/C30 -> 2.0892532 | X30: =IF(W30<=0.25,TRUE,FALSE) -> FALSE
B31: C2P1U7 | C31: 155.5 | D31: 116 | E31: =ABS(C31-D31)/C31 -> 0.25401929 | F31: =IF(E31<=0.25,TRUE,FALSE) -> FALSE | G31: 160 | H31: 0.10638889 | I31: =H31*5 -> 0.53194444 | J31: 2 | K31: =ABS(C31-G31)/C31 -> 0.028938907 | L31: =IF(K31<=0.25,TRUE,FALSE) -> TRUE | M31: 137 | N31: =ABS(C31-M31)/C31 -> 0.11897106 | O31: =IF(N31<=0.25,TRUE,FALSE) -> TRUE | P31: 132 | Q31: =ABS(C31-P31)/C31 -> 0.1511254 | R31: =IF(Q31<=0.25,TRUE,FALSE) -> TRUE | S31: 79 | T31: =ABS(C31-S31)/C31 -> 0.49196141 | U31: =IF(T31<=0.25,TRUE,FALSE) -> FALSE | V31: 480 | W31: =ABS(C31-V31)/C31 -> 2.0868167 | X31: =IF(W31<=0.25,TRUE,FALSE) -> FALSE
B32: C2P1U8 | C32: 246.5 | D32: 328 | E32: =ABS(C32-D32)/C32 -> 0.3306288 | F32: =IF(E32<=0.25,TRUE,FALSE) -> FALSE | G32: 64 | H32: 0.091666667 | I32: =H32*5 -> 0.45833333 | J32: 2 | K32: =ABS(C32-G32)/C32 -> 0.74036511 | L32: =IF(K32<=0.25,TRUE,FALSE) -> FALSE | M32: 137 | N32: =ABS(C32-M32)/C32 -> 0.44421907 | O32: =IF(N32<=0.25,TRUE,FALSE) -> FALSE | P32: 160 | Q32: =ABS(C32-P32)/C32 -> 0.35091278 | R32: =IF(Q32<=0.25,TRUE,FALSE) -> FALSE | S32: 120 | T32: =ABS(C32-S32)/C32 -> 0.51318458 | U32: =IF(T32<=0.25,TRUE,FALSE) -> FALSE | V32: 670 | W32: =ABS(C32-V32)/C32 -> 1.7180527 | X32: =IF(W32<=0.25,TRUE,FALSE) -> FALSE
B33: C2P1U9 | C33: 63 | D33: 64.5 | E33: =ABS(C33-D33)/C33 -> 0.023809524 | F33: =IF(E33<=0.25,TRUE,FALSE) -> TRUE | G33: =8*8 -> 64 | H33: 0.13472222 | I33: =H33*5 -> 0.67361111 | J33: 2 | K33: =ABS(C33-G33)/C33 -> 0.015873016 | L33: =IF(K33<=0.25,TRUE,FALSE) -> TRUE | M33: 26 | N33: =ABS(C33-M33)/C33 -> 0.58730159 | O33: =IF(N33<=0.25,TRUE,FALSE) -> FALSE | P33: 52 | Q33: =ABS(C33-P33)/C33 -> 0.17460317 | R33: =IF(Q33<=0.25,TRUE,FALSE) -> TRUE | S33: 19 | T33: =ABS(C33-S33)/C33 -> 0.6984127 | U33: =IF(T33<=0.25,TRUE,FALSE) -> FALSE | V33: 80 | W33: =ABS(C33-V33)/C33 -> 0.26984127 | X33: =IF(W33<=0.25,TRUE,FALSE) -> FALSE
B34: C2P1U10 | C34: 77.75 | D34: 84 | E34: =ABS(C34-D34)/C34 -> 0.080385852 | F34: =IF(E34<=0.25,TRUE,FALSE) -> TRUE | G34: 64 | H34: 0.10972222 | I34: =H34*5 -> 0.54861111 | J34: 3 | K34: =ABS(C34-G34)/C34 -> 0.17684887 | L34: =IF(K34<=0.25,TRUE,FALSE) -> TRUE | M34: 92 | N34: =ABS(C34-M34)/C34 -> 0.18327974 | O34: =IF(N34<=0.25,TRUE,FALSE) -> TRUE | P34: 130 | Q34: =ABS(C34-P34)/C34 -> 0.67202572 | R34: =IF(Q34<=0.25,TRUE,FALSE) -> FALSE | S34: 92 | T34: =ABS(C34-S34)/C34 -> 0.18327974 | U34: =IF(T34<=0.25,TRUE,FALSE) -> TRUE | V34: 264 | W34: =ABS(C34-V34)/C34 -> 2.3954984 | X34: =IF(W34<=0.25,TRUE,FALSE) -> FALSE
B35: C2P1U11 | C35: 209.5 | D35: 178.75 | E35: =ABS(C35-D35)/C35 -> 0.14677804 | F35: =IF(E35<=0.25,TRUE,FALSE) -> TRUE | G35: =13*8 -> 104 | H35: 0.20916667 | I35: =H35*5 -> 1.0458333 | J35: 3 | K35: =ABS(C35-G35)/C35 -> 0.50357995 | L35: =IF(K35<=0.25,TRUE,FALSE) -> FALSE | M35: 121 | N35: =ABS(C35-M35)/C35 -> 0.42243437 | O35: =IF(N35<=0.25,TRUE,FALSE) -> FALSE | P35: 134 | Q35: =ABS(C35-P35)/C35 -> 0.36038186 | R35: =IF(Q35<=0.25,TRUE,FALSE) -> FALSE | S35: 48 | T35: =ABS(C35-S35)/C35 -> 0.77088305 | U35: =IF(T35<=0.25,TRUE,FALSE) -> FALSE | V35: 195 | W35: =ABS(C35-V35)/C35 -> 0.069212411 | X35: =IF(W35<=0.25,TRUE,FALSE) -> TRUE
B36: C2P1U12 | C36: 13 | D36: 12 | E36: =ABS(C36-D36)/C36 -> 0.076923077 | F36: =IF(E36<=0.25,TRUE,FALSE) -> TRUE | G36: =8*1 -> 8 | H36: 0.056111111 | I36: =H36*5 -> 0.28055556 | J36: 2 | K36: =ABS(C36-G36)/C36 -> 0.38461538 | L36: =IF(K36<=0.25,TRUE,FALSE) -> FALSE | M36: 42 | N36: =ABS(C36-M36)/C36 -> 2.2307692 | O36: =IF(N36<=0.25,TRUE,FALSE) -> FALSE | P36: 52 | Q36: =ABS(C36-P36)/C36 -> 3 | R36: =IF(Q36<=0.25,TRUE,FALSE) -> FALSE | S36: 26 | T36: =ABS(C36-S36)/C36 -> 1 | U36: =IF(T36<=0.25,TRUE,FALSE) -> FALSE | V36: 18 | W36: =ABS(C36-V36)/C36 -> 0.38461538 | X36: =IF(W36<=0.25,TRUE,FALSE) -> FALSE
A37: Total | C37: =SUM(C25:C36) -> 1142.6 | D37: =SUM(D25:D36) -> 1055.25 | E37: =AVERAGE(E25:E36) -> 0.22107725 | F37: =COUNTIF(F25:F36,TRUE)/ROWS(B25:B36) -> 0.5 | G37: =SUM(G25:G36) -> 864 | H37: =SUM(H25:H36) -> 1.4880556 | I37: =SUM(I25:I36) -> 7.4402778 | J37: =SUM(J25:J36) -> 28 | K37: =AVERAGE(K25:K36) -> 0.32337149 | L37: =COUNTIF(L25:L36, TRUE)/ROWS(B25:B36) -> 0.58333333 | M37: =SUM(M25:M36) -> 1023 | N37: =AVERAGE(N25:N36) -> 0.60185136 | O37: =COUNTIF(O25:O36, TRUE)/ROWS(B25:B36) -> 0.33333333 | P37: =SUM(P25:P36) -> 1352 | Q37: =AVERAGE(Q25:Q36) -> 1.1347934 | R37: =COUNTIF(R25:R36, TRUE)/ROWS(B25:B36) -> 0.25 | S37: =SUM(S25:S36) -> 967 | T37: =AVERAGE(T25:T36) -> 0.91711212 | U37: =COUNTIF(U25:U36, TRUE)/ROWS(B25:B36) -> 0.083333333 | V37: =SUM(V25:V36) -> 2863 | W37: =AVERAGE(W25:W36) -> 1.9006457 | X37: =COUNTIF(X25:X36, TRUE)/ROWS(B25:B36) -> 0.083333333
A38: C2P2 | B38: C2P2U1 | C38: 61.5 | D38: 64 | E38: =ABS(C38-D38)/C38 -> 0.040650407 | F38: =IF(E38<=0.25,TRUE,FALSE) -> TRUE | G38: 104 | H38: 0.11805556 | I38: =H38*5 -> 0.59027778 | J38: 2 | K38: =ABS(C38-G38)/C38 -> 0.69105691 | L38: =IF(K38<=0.25,TRUE,FALSE) -> FALSE | M38: 73 | N38: =ABS(C38-M38)/C38 -> 0.18699187 | O38: =IF(N38<=0.25,TRUE,FALSE) -> TRUE | P38: 42 | Q38: =ABS(C38-P38)/C38 -> 0.31707317 | R38: =IF(Q38<=0.25,TRUE,FALSE) -> FALSE | S38: 31 | T38: =ABS(C38-S38)/C38 -> 0.49593496 | U38: =IF(T38<=0.25,TRUE,FALSE) -> FALSE | V38: 92 | W38: =ABS(C38-V38)/C38 -> 0.49593496 | X38: =IF(W38<=0.25,TRUE,FALSE) -> FALSE
B39: C2P2U2 | C39: 50.25 | D39: 64 | E39: =ABS(C39-D39)/C39 -> 0.27363184 | F39: =IF(E39<=0.25,TRUE,FALSE) -> FALSE | G39: 64 | H39: 0.10861111 | I39: =H39*5 -> 0.54305556 | J39: 2 | K39: =ABS(C39-G39)/C39 -> 0.27363184 | L39: =IF(K39<=0.25,TRUE,FALSE) -> FALSE | M39: 92 | N39: =ABS(C39-M39)/C39 -> 0.83084577 | O39: =IF(N39<=0.25,TRUE,FALSE) -> FALSE | P39: 50 | Q39: =ABS(C39-P39)/C39 -> 0.0049751244 | R39: =IF(Q39<=0.25,TRUE,FALSE) -> TRUE | S39: 75 | T39: =ABS(C39-S39)/C39 -> 0.49253731 | U39: =IF(T39<=0.25,TRUE,FALSE) -> FALSE | V39: 86 | W39: =ABS(C39-V39)/C39 -> 0.71144279 | X39: =IF(W39<=0.25,TRUE,FALSE) -> FALSE
B40: C2P2U3 | C40: 139.75 | D40: 126 | E40: =ABS(C40-D40)/C40 -> 0.098389982 | F40: =IF(E40<=0.25,TRUE,FALSE) -> TRUE | G40: 104 | H40: 0.10944444 | I40: =H40*5 -> 0.54722222 | J40: 3 | K40: =ABS(C40-G40)/C40 -> 0.25581395 | L40: =IF(K40<=0.25,TRUE,FALSE) -> FALSE | M40: 124 | N40: =ABS(C40-M40)/C40 -> 0.11270125 | O40: =IF(N40<=0.25,TRUE,FALSE) -> TRUE | P40: 50 | Q40: =ABS(C40-P40)/C40 -> 0.64221825 | R40: =IF(Q40<=0.25,TRUE,FALSE) -> FALSE | S40: 109 | T40: =ABS(C40-S40)/C40 -> 0.22003578 | U40: =IF(T40<=0.25,TRUE,FALSE) -> TRUE | V40: 120 | W40: =ABS(C40-V40)/C40 -> 0.14132379 | X40: =IF(W40<=0.25,TRUE,FALSE) -> TRUE
...

Sheet Estimates & Accuracy - Mobile
A1: Project | B1: User Story Key | C1: Actual Effort (PH) | D1: Expert Judgement Single Point | G1: Planning Poker | M1: ChatGPT | P1: DeepSeek | S1: Copilot | V1: Gemini
D2: Estimates (PH) | E2: MRE | F2: ± 25% | G2: Estimates (PH) | H2: Effort (Hours) | I2: Effort (PH) | J2: Iterations | K2: MRE | L2: ± 25% | M2: Estimates (PH) | N2: MRE | O2: ± 25% | P2: Estimates (PH) | Q2: MRE | R2: ± 25% | S2: Estimates (PH) | T2: MRE | U2: ± 25% | V2: Estimates (PH) | W2: MRE | X2: ± 25%
A3: C3P1 | B3: C3P1U1 | C3: 75 | D3: 64 | E3: =ABS(C3-D3)/C3 -> 0.14666667 | F3: =IF(E3<=0.25,TRUE,FALSE) -> TRUE | G3: 64 | H3: 0.10722222 | I3: =5*H3 -> 0.53611111 | J3: 3 | K3: =ABS(C3-G3)/C3 -> 0.14666667 | L3: =IF(K3<=0.25,TRUE,FALSE) -> TRUE | M3: 44 | N3: =ABS(C3-M3)/C3 -> 0.41333333 | O3: =IF(N3<=0.25,TRUE,FALSE) -> FALSE | P3: 28 | Q3: =ABS(C3-P3)/C3 -> 0.62666667 | R3: =IF(Q3<=0.25,TRUE,FALSE) -> FALSE | S3: 66 | T3: =ABS(C3-S3)/C3 -> 0.12 | U3: =IF(T3<=0.25,TRUE,FALSE) -> TRUE | V3: 37 | W3: =ABS(C3-V3)/C3 -> 0.50666667 | X3: =IF(W3<=0.25,TRUE,FALSE) -> FALSE
B4: C3P1U2 | C4: 35 | D4: 32 | E4: =ABS(C4-D4)/C4 -> 0.085714286 | F4: =IF(E4<=0.25,TRUE,FALSE) -> TRUE | G4: 40 | H4: 0.13388889 | I4: =5*H4 -> 0.66944444 | J4: 2 | K4: =ABS(C4-G4)/C4 -> 0.14285714 | L4: =IF(K4<=0.25,TRUE,FALSE) -> TRUE | M4: 38 | N4: =ABS(C4-M4)/C4 -> 0.085714286 | O4: =IF(N4<=0.25,TRUE,FALSE) -> TRUE | P4: 50 | Q4: =ABS(C4-P4)/C4 -> 0.42857143 | R4: =IF(Q4<=0.25,TRUE,FALSE) -> FALSE | S4: 52 | T4: =ABS(C4-S4)/C4 -> 0.48571429 | U4: =IF(T4<=0.25,TRUE,FALSE) -> FALSE | V4: 32 | W4: =ABS(C4-V4)/C4 -> 0.085714286 | X4: =IF(W4<=0.25,TRUE,FALSE) -> TRUE
B5: C3P1U3 | C5: 17.6 | D5: 16 | E5: =ABS(C5-D5)/C5 -> 0.090909091 | F5: =IF(E5<=0.25,TRUE,FALSE) -> TRUE | G5: 24 | H5: 0.10027778 | I5: =5*H5 -> 0.50138889 | J5: 3 | K5: =ABS(C5-G5)/C5 -> 0.36363636 | L5: =IF(K5<=0.25,TRUE,FALSE) -> FALSE | M5: 36 | N5: =ABS(C5-M5)/C5 -> 1.0454545 | O5: =IF(N5<=0.25,TRUE,FALSE) -> FALSE | P5: 80 | Q5: =ABS(C5-P5)/C5 -> 3.5454545 | R5: =IF(Q5<=0.25,TRUE,FALSE) -> FALSE | S5: 72 | T5: =ABS(C5-S5)/C5 -> 3.0909091 | U5: =IF(T5<=0.25,TRUE,FALSE) -> FALSE | V5: 58 | W5: =ABS(C5-V5)/C5 -> 2.2954545 | X5: =IF(W5<=0.25,TRUE,FALSE) -> FALSE
B6: C3P1U4 | C6: 45 | D6: 50 | E6: =ABS(C6-D6)/C6 -> 0.11111111 | F6: =IF(E6<=0.25,TRUE,FALSE) -> TRUE | G6: 64 | H6: 0.15138889 | I6: =5*H6 -> 0.75694444 | J6: 2 | K6: =ABS(C6-G6)/C6 -> 0.42222222 | L6: =IF(K6<=0.25,TRUE,FALSE) -> FALSE | M6: 25 | N6: =ABS(C6-M6)/C6 -> 0.44444444 | O6: =IF(N6<=0.25,TRUE,FALSE) -> FALSE | P6: 36 | Q6: =ABS(C6-P6)/C6 -> 0.2 | R6: =IF(Q6<=0.25,TRUE,FALSE) -> TRUE | S6: 50 | T6: =ABS(C6-S6)/C6 -> 0.11111111 | U6: =IF(T6<=0.25,TRUE,FALSE) -> TRUE | V6: 44 | W6: =ABS(C6-V6)/C6 -> 0.022222222 | X6: =IF(W6<=0.25,TRUE,FALSE) -> TRUE
B7: C3P1U5 | C7: 25.2 | D7: 24 | E7: =ABS(C7-D7)/C7 -> 0.047619048 | F7: =IF(E7<=0.25,TRUE,FALSE) -> TRUE | G7: 24 | H7: 0.095 | I7: =5*H7 -> 0.475 | J7: 2 | K7: =ABS(C7-G7)/C7 -> 0.047619048 | L7: =IF(K7<=0.25,TRUE,FALSE) -> TRUE | M7: 56 | N7: =ABS(C7-M7)/C7 -> 1.2222222 | O7: =IF(N7<=0.25,TRUE,FALSE) -> FALSE | P7: 62 | Q7: =ABS(C7-P7)/C7 -> 1.4603175 | R7: =IF(Q7<=0.25,TRUE,FALSE) -> FALSE | S7: 77 | T7: =ABS(C7-S7)/C7 -> 2.0555556 | U7: =IF(T7<=0.25,TRUE,FALSE) -> FALSE | V7: 96 | W7: =ABS(C7-V7)/C7 -> 2.8095238 | X7: =IF(W7<=0.25,TRUE,FALSE) -> FALSE
B8: C3P1U6 | C8: 71.3 | D8: 64 | E8: =ABS(C8-D8)/C8 -> 0.10238429 | F8: =IF(E8<=0.25,TRUE,FALSE) -> TRUE | G8: 64 | H8: 0.1375 | I8: =5*H8 -> 0.6875 | J8: 2 | K8: =ABS(C8-G8)/C8 -> 0.10238429 | L8: =IF(K8<=0.25,TRUE,FALSE) -> TRUE | M8: 44 | N8: =ABS(C8-M8)/C8 -> 0.3828892 | O8: =IF(N8<=0.25,TRUE,FALSE) -> FALSE | P8: 56 | Q8: =ABS(C8-P8)/C8 -> 0.21458626 | R8: =IF(Q8<=0.25,TRUE,FALSE) -> TRUE | S8: 41 | T8: =ABS(C8-S8)/C8 -> 0.42496494 | U8: =IF(T8<=0.25,TRUE,FALSE) -> FALSE | V8: 100 | W8: =ABS(C8-V8)/C8 -> 0.40252454 | X8: =IF(W8<=0.25,TRUE,FALSE) -> FALSE
B9: C3P1U7 | C9: 15.5 | D9: 20 | E9: =ABS(C9-D9)/C9 -> 0.29032258 | F9: =IF(E9<=0.25,TRUE,FALSE) -> FALSE | G9: 24 | H9: 0.094166667 | I9: =5*H9 -> 0.47083333 | J9: 2 | K9: =ABS(C9-G9)/C9 -> 0.5483871 | L9: =IF(K9<=0.25,TRUE,FALSE) -> FALSE | M9: 38 | N9: =ABS(C9-M9)/C9 -> 1.4516129 | O9: =IF(N9<=0.25,TRUE,FALSE) -> FALSE | P9: 38 | Q9: =ABS(C9-P9)/C9 -> 1.4516129 | R9: =IF(Q9<=0.25,TRUE,FALSE) -> FALSE | S9: 22 | T9: =ABS(C9-S9)/C9 -> 0.41935484 | U9: =IF(T9<=0.25,TRUE,FALSE) -> FALSE | V9: 40 | W9: =ABS(C9-V9)/C9 -> 1.5806452 | X9: =IF(W9<=0.25,TRUE,FALSE) -> FALSE
B10: C3P1U8 | C10: 22.5 | D10: 32 | E10: =ABS(C10-D10)/C10 -> 0.42222222 | F10: =IF(E10<=0.25,TRUE,FALSE) -> FALSE | G10: 64 | H10: 0.12416667 | I10: =5*H10 -> 0.62083333 | J10: 2 | K10: =ABS(C10-G10)/C10 -> 1.8444444 | L10: =IF(K10<=0.25,TRUE,FALSE) -> FALSE | M10: 36 | N10: =ABS(C10-M10)/C10 -> 0.6 | O10: =IF(N10<=0.25,TRUE,FALSE) -> FALSE | P10: 30 | Q10: =ABS(C10-P10)/C10 -> 0.33333333 | R10: =IF(Q10<=0.25,TRUE,FALSE) -> FALSE | S10: 30 | T10: =ABS(C10-S10)/C10 -> 0.33333333 | U10: =IF(T10<=0.25,TRUE,FALSE) -> FALSE | V10: 56 | W10: =ABS(C10-V10)/C10 -> 1.4888889 | X10: =IF(W10<=0.25,TRUE,FALSE) -> FALSE
B11: C3P1U9 | C11: 20.2 | D11: 20 | E11: =ABS(C11-D11)/C11 -> 0.0099009901 | F11: =IF(E11<=0.25,TRUE,FALSE) -> TRUE | G11: 24 | H11: 0.090555556 | I11: =5*H11 -> 0.45277778 | J11: 2 | K11: =ABS(C11-G11)/C11 -> 0.18811881 | L11: =IF(K11<=0.25,TRUE,FALSE) -> TRUE | M11: 36 | N11: =ABS(C11-M11)/C11 -> 0.78217822 | O11: =IF(N11<=0.25,TRUE,FALSE) -> FALSE | P11: 32 | Q11: =ABS(C11-P11)/C11 -> 0.58415842 | R11: =IF(Q11<=0.25,TRUE,FALSE) -> FALSE | S11: 40 | T11: =ABS(C11-S11)/C11 -> 0.98019802 | U11: =IF(T11<=0.25,TRUE,FALSE) -> FALSE | V11: 56 | W11: =ABS(C11-V11)/C11 -> 1.7722772 | X11: =IF(W11<=0.25,TRUE,FALSE) -> FALSE
B12: C3P1U10 | C12: 40.5 | D12: 36 | E12: =ABS(C12-D12)/C12 -> 0.11111111 | F12: =IF(E12<=0.25,TRUE,FALSE) -> TRUE | G12: 64 | H12: 0.13777778 | I12: =5*H12 -> 0.68888889 | J12: 2 | K12: =ABS(C12-G12)/C12 -> 0.58024691 | L12: =IF(K12<=0.25,TRUE,FALSE) -> FALSE | M12: 38 | N12: =ABS(C12-M12)/C12 -> 0.061728395 | O12: =IF(N12<=0.25,TRUE,FALSE) -> TRUE | P12: 50 | Q12: =ABS(C12-P12)/C12 -> 0.2345679 | R12: =IF(Q12<=0.25,TRUE,FALSE) -> TRUE | S12: 72 | T12: =ABS(C12-S12)/C12 -> 0.77777778 | U12: =IF(T12<=0.25,TRUE,FALSE) -> FALSE | V12: 168 | W12: =ABS(C12-V12)/C12 -> 3.1481481 | X12: =IF(W12<=0.25,TRUE,FALSE) -> FALSE
B13: C3P1U11 | C13: 77.3 | D13: 60 | E13: =ABS(C13-D13)/C13 -> 0.22380336 | F13: =IF(E13<=0.25,TRUE,FALSE) -> TRUE | G13: 64 | H13: 0.10861111 | I13: =5*H13 -> 0.54305556 | J13: 3 | K13: =ABS(C13-G13)/C13 -> 0.17205692 | L13: =IF(K13<=0.25,TRUE,FALSE) -> TRUE | M13: 38 | N13: =ABS(C13-M13)/C13 -> 0.5084088 | O13: =IF(N13<=0.25,TRUE,FALSE) -> FALSE | P13: 68 | Q13: =ABS(C13-P13)/C13 -> 0.12031048 | R13: =IF(Q13<=0.25,TRUE,FALSE) -> TRUE | S13: 75 | T13: =ABS(C13-S13)/C13 -> 0.029754204 | U13: =IF(T13<=0.25,TRUE,FALSE) -> TRUE | V13: 60 | W13: =ABS(C13-V13)/C13 -> 0.22380336 | X13: =IF(W13<=0.25,TRUE,FALSE) -> TRUE
A14: Total | C14: =SUM(C3:C13) -> 445.1 | D14: =SUM(D3:D13) -> 418 | E14: =AVERAGE(E3:E13) -> 0.14925134 | F14: =(COUNTIF(F3:F13, TRUE))/(ROWS(B3:B13)) -> 0.81818182 | G14: =SUM(G3:G13) -> 520 | H14: =SUM(H3:H13) -> 1.2805556 | I14: =SUM(I3:I13) -> 6.4027778 | J14: =SUM(J3:J13) -> 25 | K14: =AVERAGE(K3:K13) -> 0.41442181 | L14: =COUNTIF(L3:L13, TRUE)/ROWS(B3:B13) -> 0.54545455 | M14: =SUM(M3:M13) -> 429 | N14: =AVERAGE(N3:N13) -> 0.63618058 | O14: =COUNTIF(O3:O13,TRUE)/ROWS(B3:B13) -> 0.18181818 | P14: =SUM(P3:P13) -> 530 | Q14: =AVERAGE(Q3:Q13) -> 0.8363254 | R14: =COUNTIF(R3:R13, TRUE)/ROWS(B3:B13) -> 0.36363636 | S14: =SUM(S3:S13) -> 597 | T14: =AVERAGE(T3:T13) -> 0.80260665 | U14: =COUNTIF(U3:U13, TRUE)/ROWS(B3:B13) -> 0.27272727 | V14: =SUM(V3:V13) -> 747 | W14: =AVERAGE(W3:W13) -> 1.3032608 | X14: =COUNTIF(X3:X13, TRUE)/ROWS(B3:B13) -> 0.27272727
A15: C4P1 | B15: C4P1U1 | C15: 74 | D15: 48 | E15: =ABS(C15-D15)/C15 -> 0.35135135 | F15: =IF(E15<=0.25,TRUE,FALSE) -> FALSE | G15: 64 | H15: 0.10694444 | I15: =5*H15 -> 0.53472222 | J15: 2 | K15: =ABS(C15-G15)/C15 -> 0.13513514 | L15: =IF(K15<=0.25,TRUE,FALSE) -> TRUE | M15: 37 | N15: =ABS(C15-M15)/C15 -> 0.5 | O15: =IF(N15<=0.25,TRUE,FALSE) -> FALSE | P15: 80 | Q15: =ABS(C15-P15)/C15 -> 0.081081081 | R15: =IF(Q15<=0.25,TRUE,FALSE) -> TRUE | S15: 102 | T15: =ABS(C15-S15)/C15 -> 0.37837838 | U15: =IF(T15<=0.25,TRUE,FALSE) -> FALSE | V15: 90 | W15: =ABS(C15-V15)/C15 -> 0.21621622 | X15: =IF(W15<=0.25,TRUE,FALSE) -> TRUE
B16: C4P1U2 | C16: 53.2 | D16: 35 | E16: =ABS(C16-D16)/C16 -> 0.34210526 | F16: =IF(E16<=0.25,TRUE,FALSE) -> FALSE | G16: 40 | H16: 0.073055556 | I16: =5*H16 -> 0.36527778 | J16: 2 | K16: =ABS(C16-G16)/C16 -> 0.2481203 | L16: =IF(K16<=0.25,TRUE,FALSE) -> TRUE | M16: 34 | N16: =ABS(C16-M16)/C16 -> 0.36090226 | O16: =IF(N16<=0.25,TRUE,FALSE) -> FALSE | P16: 32 | Q16: =ABS(C16-P16)/C16 -> 0.39849624 | R16: =IF(Q16<=0.25,TRUE,FALSE) -> FALSE | S16: 57 | T16: =ABS(C16-S16)/C16 -> 0.071428571 | U16: =IF(T16<=0.25,TRUE,FALSE) -> TRUE | V16: 48 | W16: =ABS(C16-V16)/C16 -> 0.097744361 | X16: =IF(W16<=0.25,TRUE,FALSE) -> TRUE
B17: C4P1U3 | C17: 107.5 | D17: 60 | E17: =ABS(C17-D17)/C17 -> 0.44186047 | F17: =IF(E17<=0.25,TRUE,FALSE) -> FALSE | G17: 104 | H17: 0.11666667 | I17: =5*H17 -> 0.58333333 | J17: 2 | K17: =ABS(C17-G17)/C17 -> 0.03255814 | L17: =IF(K17<=0.25,TRUE,FALSE) -> TRUE | M17: 34 | N17: =ABS(C17-M17)/C17 -> 0.68372093 | O17: =IF(N17<=0.25,TRUE,FALSE) -> FALSE | P17: 28 | Q17: =ABS(C17-P17)/C17 -> 0.73953488 | R17: =IF(Q17<=0.25,TRUE,FALSE) -> FALSE | S17: 68 | T17: =ABS(C17-S17)/C17 -> 0.36744186 | U17: =IF(T17<=0.25,TRUE,FALSE) -> FALSE | V17: 44 | W17: =ABS(C17-V17)/C17 -> 0.59069767 | X17: =IF(W17<=0.25,TRUE,FALSE) -> FALSE
B18: C4P1U4 | C18: 80.5 | D18: 55 | E18: =ABS(C18-D18)/C18 -> 0.31677019 | F18: =IF(E18<=0.25,TRUE,FALSE) -> FALSE | G18: 64 | H18: 0.11916667 | I18: =5*H18 -> 0.59583333 | J18: 3 | K18: =ABS(C18-G18)/C18 -> 0.20496894 | L18: =IF(K18<=0.25,TRUE,FALSE) -> TRUE | M18: 30 | N18: =ABS(C18-M18)/C18 -> 0.62732919 | O18: =IF(N18<=0.25,TRUE,FALSE) -> FALSE | P18: 95 | Q18: =ABS(C18-P18)/C18 -> 0.18012422 | R18: =IF(Q18<=0.25,TRUE,FALSE) -> TRUE | S18: 62 | T18: =ABS(C18-S18)/C18 -> 0.22981366 | U18: =IF(T18<=0.25,TRUE,FALSE) -> TRUE | V18: 80 | W18: =ABS(C18-V18)/C18 -> 0.0062111801 | X18: =IF(W18<=0.25,TRUE,FALSE) -> TRUE
B19: C4P1U5 | C19: 51 | D19: 44 | E19: =ABS(C19-D19)/C19 -> 0.1372549 | F19: =IF(E19<=0.25,TRUE,FALSE) -> TRUE | G19: 40 | H19: 0.095277778 | I19: =5*H19 -> 0.47638889 | J19: 2 | K19: =ABS(C19-G19)/C19 -> 0.21568627 | L19: =IF(K19<=0.25,TRUE,FALSE) -> TRUE | M19: 50 | N19: =ABS(C19-M19)/C19 -> 0.019607843 | O19: =IF(N19<=0.25,TRUE,FALSE) -> TRUE | P19: 56 | Q19: =ABS(C19-P19)/C19 -> 0.098039216 | R19: =IF(Q19<=0.25,TRUE,FALSE) -> TRUE | S19: 74 | T19: =ABS(C19-S19)/C19 -> 0.45098039 | U19: =IF(T19<=0.25,TRUE,FALSE) -> FALSE | V19: 93 | W19: =ABS(C19-V19)/C19 -> 0.82352941 | X19: =IF(W19<=0.25,TRUE,FALSE) -> FALSE
B20: C4P1U6 | C20: 31.5 | D20: 28 | E20: =ABS(C20-D20)/C20 -> 0.11111111 | F20: =IF(E20<=0.25,TRUE,FALSE) -> TRUE | G20: 24 | H20: 0.10305556 | I20: =5*H20 -> 0.51527778 | J20: 2 | K20: =ABS(C20-G20)/C20 -> 0.23809524 | L20: =IF(K20<=0.25,TRUE,FALSE) -> TRUE | M20: 35 | N20: =ABS(C20-M20)/C20 -> 0.11111111 | O20: =IF(N20<=0.25,TRUE,FALSE) -> TRUE | P20: 44 | Q20: =ABS(C20-P20)/C20 -> 0.3968254 | R20: =IF(Q20<=0.25,TRUE,FALSE) -> FALSE | S20: 24 | T20: =ABS(C20-S20)/C20 -> 0.23809524 | U20: =IF(T20<=0.25,TRUE,FALSE) -> TRUE | V20: 46 | W20: =ABS(C20-V20)/C20 -> 0.46031746 | X20: =IF(W20<=0.25,TRUE,FALSE) -> FALSE
B21: C4P1U7 | C21: 45 | D21: 30 | E21: =ABS(C21-D21)/C21 -> 0.33333333 | F21: =IF(E21<=0.25,TRUE,FALSE) -> FALSE | G21: 40 | H21: 0.095 | I21: =5*H21 -> 0.475 | J21: 2 | K21: =ABS(C21-G21)/C21 -> 0.11111111 | L21: =IF(K21<=0.25,TRUE,FALSE) -> TRUE | M21: 46 | N21: =ABS(C21-M21)/C21 -> 0.022222222 | O21: =IF(N21<=0.25,TRUE,FALSE) -> TRUE | P21: 68 | Q21: =ABS(C21-P21)/C21 -> 0.51111111 | R21: =IF(Q21<=0.25,TRUE,FALSE) -> FALSE | S21: 54 | T21: =ABS(C21-S21)/C21 -> 0.2 | U21: =IF(T21<=0.25,TRUE,FALSE) -> TRUE | V21: 74 | W21: =ABS(C21-V21)/C21 -> 0.64444444 | X21: =IF(W21<=0.25,TRUE,FALSE) -> FALSE
B22: C4P1U8 | C22: 71.25 | D22: 50 | E22: =ABS(C22-D22)/C22 -> 0.29824561 | F22: =IF(E22<=0.25,TRUE,FALSE) -> FALSE | G22: 64 | H22: 0.22055556 | I22: =5*H22 -> 1.1027778 | J22: 3 | K22: =ABS(C22-G22)/C22 -> 0.10175439 | L22: =IF(K22<=0.25,TRUE,FALSE) -> TRUE | M22: 42 | N22: =ABS(C22-M22)/C22 -> 0.41052632 | O22: =IF(N22<=0.25,TRUE,FALSE) -> FALSE | P22: 72 | Q22: =ABS(C22-P22)/C22 -> 0.010526316 | R22: =IF(Q22<=0.25,TRUE,FALSE) -> TRUE | S22: 40 | T22: =ABS(C22-S22)/C22 -> 0.43859649 | U22: =IF(T22<=0.25,TRUE,FALSE) -> FALSE | V22: 184 | W22: =ABS(C22-V22)/C22 -> 1.5824561 | X22: =IF(W22<=0.25,TRUE,FALSE) -> FALSE
B23: C4P1U9 | C23: 115.75 | D23: 88 | E23: =ABS(C23-D23)/C23 -> 0.23974082 | F23: =IF(E23<=0.25,TRUE,FALSE) -> TRUE | G23: 104 | H23: 0.1175 | I23: =5*H23 -> 0.5875 | J23: 3 | K23: =ABS(C23-G23)/C23 -> 0.10151188 | L23: =IF(K23<=0.25,TRUE,FALSE) -> TRUE | M23: 38 | N23: =ABS(C23-M23)/C23 -> 0.67170626 | O23: =IF(N23<=0.25,TRUE,FALSE) -> FALSE | P23: 72 | Q23: =ABS(C23-P23)/C23 -> 0.37796976 | R23: =IF(Q23<=0.25,TRUE,FALSE) -> FALSE | S23: 66 | T23: =ABS(C23-S23)/C23 -> 0.42980562 | U23: =IF(T23<=0.25,TRUE,FALSE) -> FALSE | V23: 100 | W23: =ABS(C23-V23)/C23 -> 0.13606911 | X23: =IF(W23<=0.25,TRUE,FALSE) -> TRUE
B24: C4P1U10 | C24: 99.5 | D24: 80 | E24: =ABS(C24-D24)/C24 -> 0.1959799 | F24: =IF(E24<=0.25,TRUE,FALSE) -> TRUE | G24: 104 | H24: 0.12138889 | I24: =5*H24 -> 0.60694444 | J24: 2 | K24: =ABS(C24-G24)/C24 -> 0.045226131 | L24: =IF(K24<=0.25,TRUE,FALSE) -> TRUE | M24: 44 | N24: =ABS(C24-M24)/C24 -> 0.55778894 | O24: =IF(N24<=0.25,TRUE,FALSE) -> FALSE | P24: 106 | Q24: =ABS(C24-P24)/C24 -> 0.065326633 | R24: =IF(Q24<=0.25,TRUE,FALSE) -> TRUE | S24: 94 | T24: =ABS(C24-S24)/C24 -> 0.055276382 | U24: =IF(T24<=0.25,TRUE,FALSE) -> TRUE | V24: 130 | W24: =ABS(C24-V24)/C24 -> 0.30653266 | X24: =IF(W24<=0.25,TRUE,FALSE) -> FALSE
A25: Total | C25: =SUM(C15:C24) -> 729.2 | D25: =SUM(D15:D24) -> 518 | E25: =AVERAGE(E15:E24) -> 0.27677529 | F25: =COUNTIF(F15:F24, TRUE)/ROWS(B15:B24) -> 0.4 | G25: =SUM(G15:G24) -> 648 | H25: =SUM(H15:H24) -> 1.1686111 | I25: =SUM(I15:I24) -> 5.8430556 | J25: =SUM(J15:J24) -> 23 | K25: =AVERAGE(K15:K24) -> 0.14341675 | L25: =COUNTIF(L15:L24, TRUE)/ROWS(B15:B24) -> 1 | M25: =SUM(M15:M24) -> 390 | N25: =AVERAGE(N15:N24) -> 0.39649151 | O25: =COUNTIF(O15:O24, TRUE)/ROWS(B15:B24) -> 0.3 | P25: =SUM(P15:P24) -> 653 | Q25: =AVERAGE(Q15:Q24) -> 0.28590349 | R25: =COUNTIF(R15:R24, TRUE)/ROWS(B15:B24) -> 0.5 | S25: =SUM(S15:S24) -> 641 | T25: =AVERAGE(T15:T24) -> 0.28598166 | U25: =COUNTIF(U15:U24, TRUE)/ROWS(B15:B24) -> 0.5 | V25: =SUM(V15:V24) -> 889 | W25: =AVERAGE(W15:W24) -> 0.48642187 | X25: =COUNTIF(X15:X24, TRUE)/ROWS(B15:B24) -> 0.4
A26: C5P1 | B26: C5P1U1 | C26: 56.25 | D26: 50 | E26: =ABS(C26-D26)/C26 -> 0.11111111 | F26: =IF(E26<=0.25,TRUE,FALSE) -> TRUE | G26: 40 | H26: 0.10944444 | I26: =5*H26 -> 0.54722222 | J26: 2 | K26: =ABS(C26-G26)/C26 -> 0.28888889 | L26: =IF(K26<=0.25,TRUE,FALSE) -> FALSE | M26: 42 | N26: =ABS(C26-M26)/C26 -> 0.25333333 | O26: =IF(N26<=0.25,TRUE,FALSE) -> FALSE | P26: 46 | Q26: =ABS(C26-P26)/C26 -> 0.18222222 | R26: =IF(Q26<=0.25,TRUE,FALSE) -> TRUE | S26: 68 | T26: =ABS(C26-S26)/C26 -> 0.20888889 | U26: =IF(T26<=0.25,TRUE,FALSE) -> TRUE | V26: 48 | W26: =ABS(C26-V26)/C26 -> 0.14666667 | X26: =IF(W26<=0.25,TRUE,FALSE) -> TRUE
B27: C5P1U2 | C27: 35.85 | D27: 32 | E27: =ABS(C27-D27)/C27 -> 0.10739191 | F27: =IF(E27<=0.25,TRUE,FALSE) -> TRUE | G27: 40 | H27: 0.12666667 | I27: =5*H27 -> 0.63333333 | J27: 2 | K27: =ABS(C27-G27)/C27 -> 0.11576011 | L27: =IF(K27<=0.25,TRUE,FALSE) -> TRUE | M27: 33 | N27: =ABS(C27-M27)/C27 -> 0.079497908 | O27: =IF(N27<=0.25,TRUE,FALSE) -> TRUE | P27: 22 | Q27: =ABS(C27-P27)/C27 -> 0.38633194 | R27: =IF(Q27<=0.25,TRUE,FALSE) -> FALSE | S27: 41 | T27: =ABS(C27-S27)/C27 -> 0.14365411 | U27: =IF(T27<=0.25,TRUE,FALSE) -> TRUE | V27: 62 | W27: =ABS(C27-V27)/C27 -> 0.72942817 | X27: =IF(W27<=0.25,TRUE,FALSE) -> FALSE
B28: C5P1U3 | C28: 49.9 | D28: 40 | E28: =ABS(C28-D28)/C28 -> 0.19839679 | F28: =IF(E28<=0.25,TRUE,FALSE) -> TRUE | G28: 40 | H28: 0.089722222 | I28: =5*H28 -> 0.44861111 | J28: 2 | K28: =ABS(C28-G28)/C28 -> 0.19839679 | L28: =IF(K28<=0.25,TRUE,FALSE) -> TRUE | M28: 44 | N28: =ABS(C28-M28)/C28 -> 0.11823647 | O28: =IF(N28<=0.25,TRUE,FALSE) -> TRUE | P28: 62 | Q28: =ABS(C28-P28)/C28 -> 0.24248497 | R28: =IF(Q28<=0.25,TRUE,FALSE) -> TRUE | S28: 32 | T28: =ABS(C28-S28)/C28 -> 0.35871743 | U28: =IF(T28<=0.25,TRUE,FALSE) -> FALSE | V28: 66 | W28: =ABS(C28-V28)/C28 -> 0.32264529 | X28: =IF(W28<=0.25,TRUE,FALSE) -> FALSE
B29: C5P1U4 | C29: 63.3 | D29: 48 | E29: =ABS(C29-D29)/C29 -> 0.24170616 | F29: =IF(E29<=0.25,TRUE,FALSE) -> TRUE | G29: 40 | H29: 0.12222222 | I29: =5*H29 -> 0.61111111 | J29: 2 | K29: =ABS(C29-G29)/C29 -> 0.36808847 | L29: =IF(K29<=0.25,TRUE,FALSE) -> FALSE | M29: 36 | N29: =ABS(C29-M29)/C29 -> 0.43127962 | O29: =IF(N29<=0.25,TRUE,FALSE) -> FALSE | P29: 44 | Q29: =ABS(C29-P29)/C29 -> 0.30489731 | R29: =IF(Q29<=0.25,TRUE,FALSE) -> FALSE | S29: 24 | T29: =ABS(C29-S29)/C29 -> 0.62085308 | U29: =IF(T29<=0.25,TRUE,FALSE) -> FALSE | V29: 44 | W29: =ABS(C29-V29)/C29 -> 0.30489731 | X29: =IF(W29<=0.25,TRUE,FALSE) -> FALSE
B30: C5P1U5 | C30: 42.3 | D30: 50 | E30: =ABS(C30-D30)/C30 -> 0.1820331 | F30: =IF(E30<=0.25,TRUE,FALSE) -> TRUE | G30: 64 | H30: 0.094166667 | I30: =5*H30 -> 0.47083333 | J30: 2 | K30: =ABS(C30-G30)/C30 -> 0.51300236 | L30: =IF(K30<=0.25,TRUE,FALSE) -> FALSE | M30: 62 | N30: =ABS(C30-M30)/C30 -> 0.46572104 | O30: =IF(N30<=0.25,TRUE,FALSE) -> FALSE | P30: 62 | Q30: =ABS(C30-P30)/C30 -> 0.46572104 | R30: =IF(Q30<=0.25,TRUE,FALSE) -> FALSE | S30: 40 | T30: =ABS(C30-S30)/C30 -> 0.054373522 | U30: =IF(T30<=0.25,TRUE,FALSE) -> TRUE | V30: 80 | W30: =ABS(C30-V30)/C30 -> 0.89125296 | X30: =IF(W30<=0.25,TRUE,FALSE) -> FALSE
B31: C5P1U6 | C31: 85.75 | D31: 90 | E31: =ABS(C31-D31)/C31 -> 0.049562682 | F31: =IF(E31<=0.25,TRUE,FALSE) -> TRUE | G31: 104 | H31: 0.11527778 | I31: =5*H31 -> 0.57638889 | J31: 2 | K31: =ABS(C31-G31)/C31 -> 0.21282799 | L31: =IF(K31<=0.25,TRUE,FALSE) -> TRUE | M31: 65 | N31: =ABS(C31-M31)/C31 -> 0.24198251 | O31: =IF(N31<=0.25,TRUE,FALSE) -> TRUE | P31: 100 | Q31: =ABS(C31-P31)/C31 -> 0.16618076 | R31: =IF(Q31<=0.25,TRUE,FALSE) -> TRUE | S31: 88 | T31: =ABS(C31-S31)/C31 -> 0.026239067 | U31: =IF(T31<=0.25,TRUE,FALSE) -> TRUE | V31: 180 | W31: =ABS(C31-V31)/C31 -> 1.0991254 | X31: =IF(W31<=0.25,TRUE,FALSE) -> FALSE
B32: C5P1U7 | C32: 89.9 | D32: 65 | E32: =ABS(C32-D32)/C32 -> 0.27697442 | F32: =IF(E32<=0.25,TRUE,FALSE) -> FALSE | G32: 104 | H32: 0.091111111 | I32: =5*H32 -> 0.45555556 | J32: 2 | K32: =ABS(C32-G32)/C32 -> 0.15684093 | L32: =IF(K32<=0.25,TRUE,FALSE) -> TRUE | M32: 78 | N32: =ABS(C32-M32)/C32 -> 0.1323693 | O32: =IF(N32<=0.25,TRUE,FALSE) -> TRUE | P32: 58 | Q32: =ABS(C32-P32)/C32 -> 0.35483871 | R32: =IF(Q32<=0.25,TRUE,FALSE) -> FALSE | S32: 88 | T32: =ABS(C32-S32)/C32 -> 0.021134594 | U32: =IF(T32<=0.25,TRUE,FALSE) -> TRUE | V32: 130 | W32: =ABS(C32-V32)/C32 -> 0.44605117 | X32: =IF(W32<=0.25,TRUE,FALSE) -> FALSE
B33: C5P1U8 | C33: 144.25 | D33: 100 | E33: =ABS(C33-D33)/C33 -> 0.3067591 | F33: =IF(E33<=0.25,TRUE,FALSE) -> FALSE | G33: 160 | H33: 0.077222222 | I33: =5*H33 -> 0.38611111 | J33: 2 | K33: =ABS(C33-G33)/C33 -> 0.10918544 | L33: =IF(K33<=0.25,TRUE,FALSE) -> TRUE | M33: 72 | N33: =ABS(C33-M33)/C33 -> 0.50086655 | O33: =IF(N33<=0.25,TRUE,FALSE) -> FALSE | P33: 72 | Q33: =ABS(C33-P33)/C33 -> 0.50086655 | R33: =IF(Q33<=0.25,TRUE,FALSE) -> FALSE | S33: 80 | T33: =ABS(C33-S33)/C33 -> 0.44540728 | U33: =IF(T33<=0.25,TRUE,FALSE) -> FALSE | V33: 110 | W33: =ABS(C33-V33)/C33 -> 0.23743501 | X33: =IF(W33<=0.25,TRUE,FALSE) -> TRUE
B34: C5P1U9 | C34: 65 | D34: 72 | E34: =ABS(C34-D34)/C34 -> 0.10769231 | F34: =IF(E34<=0.25,TRUE,FALSE) -> TRUE | G34: 104 | H34: 0.1125 | I34: =5*H34 -> 0.5625 | J34: 2 | K34: =ABS(C34-G34)/C34 -> 0.6 | L34: =IF(K34<=0.25,TRUE,FALSE) -> FALSE | M34: 74 | N34: =ABS(C34-M34)/C34 -> 0.13846154 | O34: =IF(N34<=0.25,TRUE,FALSE) -> TRUE | P34: 150 | Q34: =ABS(C34-P34)/C34 -> 1.3076923 | R34: =IF(Q34<=0.25,TRUE,FALSE) -> FALSE | S34: 93 | T34: =ABS(C34-S34)/C34 -> 0.43076923 | U34: =IF(T34<=0.25,TRUE,FALSE) -> FALSE | V34: 116 | W34: =ABS(C34-V34)/C34 -> 0.78461538 | X34: =IF(W34<=0.25,TRUE,FALSE) -> FALSE
B35: C5P1U10 | C35: 42 | D35: 44 | E35: =ABS(C35-D35)/C35 -> 0.047619048 | F35: =IF(E35<=0.25,TRUE,FALSE) -> TRUE | G35: 40 | H35: 0.10361111 | I35: =5*H35 -> 0.51805556 | J35: 2 | K35: =ABS(C35-G35)/C35 -> 0.047619048 | L35: =IF(K35<=0.25,TRUE,FALSE) -> TRUE | M35: 47 | N35: =ABS(C35-M35)/C35 -> 0.11904762 | O35: =IF(N35<=0.25,TRUE,FALSE) -> TRUE | P35: 56 | Q35: =ABS(C35-P35)/C35 -> 0.33333333 | R35: =IF(Q35<=0.25,TRUE,FALSE) -> FALSE | S35: 120 | T35: =ABS(C35-S35)/C35 -> 1.8571429 | U35: =IF(T35<=0.25,TRUE,FALSE) -> FALSE | V35: 100 | W35: =ABS(C35-V35)/C35 -> 1.3809524 | X35: =IF(W35<=0.25,TRUE,FALSE) -> FALSE
A36: Total | C36: =SUM(C26:C35) -> 674.5 | D36: =SUM(D26:D35) -> 591 | E36: =AVERAGE(E26:E35) -> 0.16292466 | F36: =COUNTIF(F26:F35, TRUE)/ROWS(B26:B35) -> 0.8 | G36: =SUM(G26:G35) -> 736 | H36: =SUM(H26:H35) -> 1.0419444 | I36: =SUM(I26:I35) -> 5.2097222 | J36: =SUM(J26:J35) -> 20 | K36: =AVERAGE(K26:K35) -> 0.261061 | L36: =COUNTIF(L26:L35, TRUE)/ROWS(B26:B35) -> 0.6 | M36: =SUM(M26:M35) -> 553 | N36: =AVERAGE(N26:N35) -> 0.24807959 | O36: =COUNTIF(O26:O35, TRUE)/ROWS(B26:B35) -> 0.6 | P36: =SUM(P26:P35) -> 672 | Q36: =AVERAGE(Q26:Q35) -> 0.42445691 | R36: =COUNTIF(R26:R35, TRUE)/ROWS(B26:B35) -> 0.3 | S36: =SUM(S26:S35) -> 674 | T36: =AVERAGE(T26:T35) -> 0.41671801 | U36: =COUNTIF(U26:U35, TRUE)/ROWS(B26:B35) -> 0.5 | V36: =SUM(V26:V35) -> 936 | W36: =AVERAGE(W26:W35) -> 0.63430697 | X36: =COUNTIF(X26:X35, TRUE)/ROWS(B26:B35) -> 0.2
A37: C6P1 | B37: C6P1U1 | C37: 201.5 | D37: 130 | E37: =ABS(C37-D37)/C37 -> 0.35483871 | F37: =IF(E37<=0.25,TRUE,FALSE) -> FALSE | G37: 160 | H37: 0.13222222 | I37: =5*H37 -> 0.66111111 | J37: 3 | K37: =ABS(C37-G37)/C37 -> 0.20595533 | L37: =IF(K37<=0.25,TRUE,FALSE) -> TRUE | M37: 114 | N37: =ABS(C37-M37)/C37 -> 0.43424318 | O37: =IF(N37<=0.25,TRUE,FALSE) -> FALSE | P37: 52 | Q37: =ABS(C37-P37)/C37 -> 0.74193548 | R37: =IF(Q37<=0.25,TRUE,FALSE) -> FALSE | S37: 91 | T37: =ABS(C37-S37)/C37 -> 0.5483871 | U37: =IF(T37<=0.25,TRUE,FALSE) -> FALSE | V37: 230 | W37: =ABS(C37-V37)/C37 -> 0.14143921 | X37: =IF(W37<=0.25,TRUE,FALSE) -> TRUE
B38: C6P1U2 | C38: 95 | D38: 96 | E38: =ABS(C38-D38)/C38 -> 0.010526316 | F38: =IF(E38<=0.25,TRUE,FALSE) -> TRUE | G38: 104 | H38: 0.15027778 | I38: =5*H38 -> 0.75138889 | J38: 2 | K38: =ABS(C38-G38)/C38 -> 0.094736842 | L38: =IF(K38<=0.25,TRUE,FALSE) -> TRUE | M38: 180 | N38: =ABS(C38-M38)/C38 -> 0.89473684 | O38: =IF(N38<=0.25,TRUE,FALSE) -> FALSE | P38: 80 | Q38: =ABS(C38-P38)/C38 -> 0.15789474 | R38: =IF(Q38<=0.25,TRUE,FALSE) -> TRUE | S38: 135 | T38: =ABS(C38-S38)/C38 -> 0.42105263 | U38: =IF(T38<=0.25,TRUE,FALSE) -> FALSE | V38: 130 | W38: =ABS(C38-V38)/C38 -> 0.36842105 | X38: =IF(W38<=0.25,TRUE,FALSE) -> FALSE
B39: C6P1U3 | C39: 103 | D39: 80 | E39: =ABS(C39-D39)/C39 -> 0.22330097 | F39: =IF(E39<=0.25,TRUE,FALSE) -> TRUE | G39: 104 | H39: 0.085277778 | I39: =5*H39 -> 0.42638889 | J39: 2 | K39: =ABS(C39-G39)/C39 -> 0.0097087379 | L39: =IF(K39<=0.25,TRUE,FALSE) -> TRUE | M39: 126 | N39: =ABS(C39-M39)/C39 -> 0.22330097 | O39: =IF(N39<=0.25,TRUE,FALSE) -> TRUE | P39: 80 | Q39: =ABS(C39-P39)/C39 -> 0.22330097 | R39: =IF(Q39<=0.25,TRUE,FALSE) -> TRUE | S39: 108 | T39: =ABS(C39-S39)/C39 -> 0.048543689 | U39: =IF(T39<=0.25,TRUE,FALSE) -> TRUE | V39: 200 | W39: =ABS(C39-V39)/C39 -> 0.94174757 | X39: =IF(W39<=0.25,TRUE,FALSE) -> FALSE
B40: C6P1U4 | C40: 68.5 | D40: 40 | E40: =ABS(C40-D40)/C40 -> 0.41605839 | F40: =IF(E40<=0.25,TRUE,FALSE) -> FALSE | G40: 64 | H40: 0.11138889 | I40: =5*H40 -> 0.55694444 | J40: 2 | K40: =ABS(C40-G40)/C40 -> 0.065693431 | L40: =IF(K40<=0.25,TRUE,FALSE) -> TRUE | M40: 100 | N40: =ABS(C40-M40)/C40 -> 0.45985401 | O40: =IF(N40<=0.25,TRUE,FALSE) -> FALSE | P40: 60 | Q40: =ABS(C40-P40)/C40 -> 0.12408759 | R40: =IF(Q40<=0.25,TRUE,FALSE) -> TRUE | S40: 76 | T40: =ABS(C40-S40)/C40 -> 0.10948905 | U40: =IF(T40<=0.25,TRUE,FALSE) -> TRUE | V40: 88 | W40: =ABS(C40-V40)/C40 -> 0.28467153 | X40: =IF(W40<=0.25,TRUE,FALSE) -> FALSE
...

Sheet MMRE | PRED
A1: Project | B1: Platform | C1: MMRE | I1: PRED
C2: EJ (SP) | D2: PP | E2: ChatGPT | F2: DeepSeek | G2: Copilot | H2: Gemini | I2: EJ (SP) | J2: PP | K2: ChatGPT | L2: DeepSeek | M2: Copilot | N2: Gemini
A3: C1P1 | B3: Web | C3: ='Estimates & Accuracy - Web'!E10 -> 0.19448743 | D3: ='Estimates & Accuracy - Web'!K10 -> 0.36148215 | E3: ='Estimates & Accuracy - Web'!N10 -> 3.156513 | F3: ='Estimates & Accuracy - Web'!Q10 -> 6.3901907 | G3: ='Estimates & Accuracy - Web'!T10 -> 4.5218635 | H3: ='Estimates & Accuracy - Web'!W10 -> 13.392731 | I3: ='Estimates & Accuracy - Web'!F10 -> 0.71428571 | J3: ='Estimates & Accuracy - Web'!L10 -> 0.57142857 | K3: ='Estimates & Accuracy - Web'!O10 -> 0 | L3: ='Estimates & Accuracy - Web'!R10 -> 0 | M3: ='Estimates & Accuracy - Web'!U10 -> 0 | N3: ='Estimates & Accuracy - Web'!X10 -> 0
A4: C1P2 | B4: Web | C4: ='Estimates & Accuracy - Web'!E24 -> 0.17069682 | D4: ='Estimates & Accuracy - Web'!K24 -> 0.33762196 | E4: ='Estimates & Accuracy - Web'!N24 -> 0.4287777 | F4: ='Estimates & Accuracy - Web'!Q24 -> 0.6998297 | G4: ='Estimates & Accuracy - Web'!T24 -> 1.086397 | H4: ='Estimates & Accuracy - Web'!W24 -> 1.9272553 | I4: ='Estimates & Accuracy - Web'!F24 -> 0.69230769 | J4: ='Estimates & Accuracy - Web'!L24 -> 0.53846154 | K4: ='Estimates & Accuracy - Web'!O24 -> 0.46153846 | L4: ='Estimates & Accuracy - Web'!R24 -> 0.38461538 | M4: ='Estimates & Accuracy - Web'!U24 -> 0.076923077 | N4: ='Estimates & Accuracy - Web'!X24 -> 0
A5: C2P1 | B5: Web | C5: ='Estimates & Accuracy - Web'!E37 -> 0.22107725 | D5: ='Estimates & Accuracy - Web'!K37 -> 0.32337149 | E5: ='Estimates & Accuracy - Web'!N37 -> 0.60185136 | F5: ='Estimates & Accuracy - Web'!Q37 -> 1.1347934 | G5: ='Estimates & Accuracy - Web'!T37 -> 0.91711212 | H5: ='Estimates & Accuracy - Web'!W37 -> 1.9006457 | I5: ='Estimates & Accuracy - Web'!F37 -> 0.5 | J5: ='Estimates & Accuracy - Web'!L37 -> 0.58333333 | K5: ='Estimates & Accuracy - Web'!O37 -> 0.33333333 | L5: ='Estimates & Accuracy - Web'!R37 -> 0.25 | M5: ='Estimates & Accuracy - Web'!U37 -> 0.083333333 | N5: ='Estimates & Accuracy - Web'!X37 -> 0.083333333
A6: C2P2 | B6: Web | C6: ='Estimates & Accuracy - Web'!E48 -> 0.22564744 | D6: ='Estimates & Accuracy - Web'!K48 -> 0.83945529 | E6: ='Estimates & Accuracy - Web'!N48 -> 2.647892 | F6: ='Estimates & Accuracy - Web'!Q48 -> 0.87138924 | G6: ='Estimates & Accuracy - Web'!T48 -> 1.8027047 | H6: ='Estimates & Accuracy - Web'!W48 -> 2.5060226 | I6: ='Estimates & Accuracy - Web'!F48 -> 0.5 | J6: ='Estimates & Accuracy - Web'!L48 -> 0.2 | K6: ='Estimates & Accuracy - Web'!O48 -> 0.2 | L6: ='Estimates & Accuracy - Web'!R48 -> 0.1 | M6: ='Estimates & Accuracy - Web'!U48 -> 0.1 | N6: ='Estimates & Accuracy - Web'!X48 -> 0.1
A7: C2P3 | B7: Web | C7: ='Estimates & Accuracy - Web'!E57 -> 0.18029755 | D7: ='Estimates & Accuracy - Web'!K57 -> 0.37803504 | E7: ='Estimates & Accuracy - Web'!N57 -> 0.84286131 | F7: ='Estimates & Accuracy - Web'!Q57 -> 1.1535473 | G7: ='Estimates & Accuracy - Web'!T57 -> 0.41176471 | H7: ='Estimates & Accuracy - Web'!W57 -> 1.2956803 | I7: ='Estimates & Accuracy - Web'!F57 -> 0.875 | J7: ='Estimates & Accuracy - Web'!L57 -> 0.625 | K7: ='Estimates & Accuracy - Web'!O57 -> 0.25 | L7: ='Estimates & Accuracy - Web'!R57 -> 0.125 | M7: ='Estimates & Accuracy - Web'!U57 -> 0.625 | N7: ='Estimates & Accuracy - Web'!X57 -> 0.375
A8: C7P1 | B8: Web | C8: ='Estimates & Accuracy - Web'!E68 -> 0.13106535 | D8: ='Estimates & Accuracy - Web'!K68 -> 0.21719988 | E8: ='Estimates & Accuracy - Web'!N68 -> 0.20216944 | F8: ='Estimates & Accuracy - Web'!Q68 -> 0.34726205 | G8: ='Estimates & Accuracy - Web'!T68 -> 0.46349656 | H8: ='Estimates & Accuracy - Web'!W68 -> 0.3136718 | I8: ='Estimates & Accuracy - Web'!F68 -> 0.8 | J8: ='Estimates & Accuracy - Web'!L68 -> 0.6 | K8: ='Estimates & Accuracy - Web'!O68 -> 0.7 | L8: ='Estimates & Accuracy - Web'!R68 -> 0.4 | M8: ='Estimates & Accuracy - Web'!U68 -> 0.2 | N8: ='Estimates & Accuracy - Web'!X68 -> 0.5
B9: Web | C9: 0
A10: C3P1 | B10: Mobile | C10: ='Estimates & Accuracy - Mobile'!E14 -> 0.14925134 | D10: ='Estimates & Accuracy - Mobile'!K14 -> 0.41442181 | E10: ='Estimates & Accuracy - Mobile'!N14 -> 0.63618058 | F10: ='Estimates & Accuracy - Mobile'!Q14 -> 0.8363254 | G10: ='Estimates & Accuracy - Mobile'!T14 -> 0.80260665 | H10: ='Estimates & Accuracy - Mobile'!W14 -> 1.3032608 | I10: ='Estimates & Accuracy - Mobile'!F14 -> 0.81818182 | J10: ='Estimates & Accuracy - Mobile'!L14 -> 0.54545455 | K10: ='Estimates & Accuracy - Mobile'!O14 -> 0.18181818 | L10: ='Estimates & Accuracy - Mobile'!R14 -> 0.36363636 | M10: ='Estimates & Accuracy - Mobile'!U14 -> 0.27272727 | N10: ='Estimates & Accuracy - Mobile'!X14 -> 0.27272727
A11: C4P1 | B11: Mobile | C11: ='Estimates & Accuracy - Mobile'!E25 -> 0.27677529 | D11: ='Estimates & Accuracy - Mobile'!K25 -> 0.14341675 | E11: ='Estimates & Accuracy - Mobile'!N25 -> 0.39649151 | F11: ='Estimates & Accuracy - Mobile'!Q25 -> 0.28590349 | G11: ='Estimates & Accuracy - Mobile'!T25 -> 0.28598166 | H11: ='Estimates & Accuracy - Mobile'!W25 -> 0.48642187 | I11: ='Estimates & Accuracy - Mobile'!F25 -> 0.4 | J11: ='Estimates & Accuracy - Mobile'!L25 -> 1 | K11: ='Estimates & Accuracy - Mobile'!O25 -> 0.3 | L11: ='Estimates & Accuracy - Mobile'!R25 -> 0.5 | M11: ='Estimates & Accuracy - Mobile'!U25 -> 0.5 | N11: ='Estimates & Accuracy - Mobile'!X25 -> 0.4
A12: C5P1 | B12: Mobile | C12: ='Estimates & Accuracy - Mobile'!E36 -> 0.16292466 | D12: ='Estimates & Accuracy - Mobile'!K36 -> 0.261061 | E12: ='Estimates & Accuracy - Mobile'!N36 -> 0.24807959 | F12: ='Estimates & Accuracy - Mobile'!Q36 -> 0.42445691 | G12: ='Estimates & Accuracy - Mobile'!T36 -> 0.41671801 | H12: ='Estimates & Accuracy - Mobile'!W36 -> 0.63430697 | I12: ='Estimates & Accuracy - Mobile'!F36 -> 0.8 | J12: ='Estimates & Accuracy - Mobile'!L36 -> 0.6 | K12: ='Estimates & Accuracy - Mobile'!O36 -> 0.6 | L12: ='Estimates & Accuracy - Mobile'!R36 -> 0.3 | M12: ='Estimates & Accuracy - Mobile'!U36 -> 0.5 | N12: ='Estimates & Accuracy - Mobile'!X36 -> 0.2
A13: C6P1 | B13: Mobile | C13: ='Estimates & Accuracy - Mobile'!E46 -> 0.25549057 | D13: ='Estimates & Accuracy - Mobile'!K46 -> 0.12128768 | E13: ='Estimates & Accuracy - Mobile'!N46 -> 0.70145354 | F13: ='Estimates & Accuracy - Mobile'!Q46 -> 0.27554057 | G13: ='Estimates & Accuracy - Mobile'!T46 -> 0.39564404 | H13: ='Estimates & Accuracy - Mobile'!W46 -> 1.0373774 | I13: ='Estimates & Accuracy - Mobile'!F46 -> 0.44444444 | J13: ='Estimates & Accuracy - Mobile'!L46 -> 1 | K13: ='Estimates & Accuracy - Mobile'!O46 -> 0.11111111 | L13: ='Estimates & Accuracy - Mobile'!R46 -> 0.66666667 | M13: ='Estimates & Accuracy - Mobile'!U46 -> 0.33333333 | N13: ='Estimates & Accuracy - Mobile'!X46 -> 0.22222222
A14: C5P2 | B14: Mobile | C14: ='Estimates & Accuracy - Mobile'!E57 -> 0.24110041 | D14: ='Estimates & Accuracy - Mobile'!K57 -> 0.23966858 | E14: ='Estimates & Accuracy - Mobile'!N57 -> 0.41705628 | F14: ='Estimates & Accuracy - Mobile'!Q57 -> 0.45081368 | G14: ='Estimates & Accuracy - Mobile'!T57 -> 0.49681299 | H14: ='Estimates & Accuracy - Mobile'!W57 -> 0.4230146 | I14: ='Estimates & Accuracy - Mobile'!F57 -> 0.4 | J14: ='Estimates & Accuracy - Mobile'!L57 -> 0.6 | K14: ='Estimates & Accuracy - Mobile'!O57 -> 0.2 | L14: ='Estimates & Accuracy - Mobile'!R57 -> 0.4 | M14: ='Estimates & Accuracy - Mobile'!U57 -> 0.1 | N14: ='Estimates & Accuracy - Mobile'!X57 -> 0.3
B15: Mobile | C15: 0

Sheet % of Best MRE
A1: Project | B1: Total User Stories | C1: Expert Judgement Single Point | E1: Planning Poker | G1: ChatGPT | I1: DeepSeek | K1: Copilot | M1: Gemini
A2: C1P1 | B2: =ROWS('Estimates & Accuracy - Web'!B3:B9) -> 7 | C2: =SUMPRODUCT(--('Estimates & Accuracy - Web'!E3:E9 <= 'Estimates & Accuracy - Web'!K3:K9), --('Estimates & Accuracy - Web'!E3:E9 <= 'Estimates & Accuracy - Web'!N3:N9), --('Estimates & Accuracy - Web'!E3:E9 <= 'Estimates & Accuracy - Web'!Q3:Q9), --('Estimates & Accuracy - Web'!E3:E9 <= 'Estimates & Accuracy - Web'!T3:T9), --('Estimates & Accuracy - Web'!E3:E9 <= 'Estimates & Accuracy - Web'!W3:W9) ) -> 6 | D2: =C2/B2 -> 0.85714286 | E2: =SUMPRODUCT(--('Estimates & Accuracy - Web'!K3:K9 <= 'Estimates & Accuracy - Web'!E3:E9),--('Estimates & Accuracy - Web'!K3:K9 <= 'Estimates & Accuracy - Web'!N3:N9),--('Estimates & Accuracy - Web'!K3:K9 <= 'Estimates & Accuracy - Web'!Q3:Q9),--('Estimates & Accuracy - Web'!K3:K9 <= 'Estimates & Accuracy - Web'!T3:T9),--('Estimates & Accuracy - Web'!K3:K9 <= 'Estimates & Accuracy - Web'!W3:W9) ) -> 3 | F2: =E2/B2 -> 0.42857143 | G2: =SUMPRODUCT(--('Estimates & Accuracy - Web'!N3:N9 <= 'Estimates & Accuracy - Web'!E3:E9), --('Estimates & Accuracy - Web'!N3:N9 <= 'Estimates & Accuracy - Web'!K3:K9), --('Estimates & Accuracy - Web'!N3:N9 <= 'Estimates & Accuracy - Web'!Q3:Q9), --('Estimates & Accuracy - Web'!N3:N9 <= 'Estimates & Accuracy - Web'!T3:T9), --('Estimates & Accuracy - Web'!N3:N9 <= 'Estimates & Accuracy - Web'!W3:W9) ) -> 0 | H2: =G2/B2 -> 0 | I2: =SUMPRODUCT(--('Estimates & Accuracy - Web'!Q3:Q9 <= 'Estimates & Accuracy - Web'!E3:E9), --('Estimates & Accuracy - Web'!Q3:Q9 <= 'Estimates & Accuracy - Web'!K3:K9), --('Estimates & Accuracy - Web'!Q3:Q9 <= 'Estimates & Accuracy - Web'!N3:N9), --('Estimates & Accuracy - Web'!Q3:Q9 <= 'Estimates & Accuracy - Web'!T3:T9), --('Estimates & Accuracy - Web'!Q3:Q9 <= 'Estimates & Accuracy - Web'!W3:W9) ) -> 0 | J2: =I2/B2 -> 0 | K2: =SUMPRODUCT(--('Estimates & Accuracy - Web'!T3:T9 <= 'Estimates & Accuracy - Web'!E3:E9), --('Estimates & Accuracy - Web'!T3:T9 <= 'Estimates & Accuracy - Web'!K3:K9), --('Estimates & Accuracy - Web'!T3:T9 <= 'Estimates & Accuracy - Web'!N3:N9), --('Estimates & Accuracy - Web'!T3:T9 <= 'Estimates & Accuracy - Web'!Q3:Q9), --('Estimates & Accuracy - Web'!T3:T9 <= 'Estimates & Accuracy - Web'!W3:W9) ) -> 0 | L2: =K2/B2 -> 0 | M2: =SUMPRODUCT(--('Estimates & Accuracy - Web'!W3:W9 <= 'Estimates & Accuracy - Web'!E3:E9), --('Estimates & Accuracy - Web'!W3:W9 <= 'Estimates & Accuracy - Web'!K3:K9), --('Estimates & Accuracy - Web'!W3:W9 <= 'Estimates & Accuracy - Web'!N3:N9), --('Estimates & Accuracy - Web'!W3:W9 <= 'Estimates & Accuracy - Web'!Q3:Q9), --('Estimates & Accuracy - Web'!W3:W9 <= 'Estimates & Accuracy - Web'!T3:T9) ) -> 0 | N2: =M2/B2 -> 0
